Workbook

Sheet How To Use
B2: Project Resource Sheet 관리
B4: 1. New Project Sheet Creation
C5: A | D5: Temp. V00 sheet를 copy하여 sheet 이름을 수정하여 >< (검정색 화살표) 사이로 sheet를 옮긴다.
C6: B | D6: 검정색 화살표 사이에 Sheet를 넣으면 자동으로 SheetMerge로 Data가 통합된다.
C7: C | D7: Temp. V00
D8: * | E8: 연두색 - 입력 혹은 선택 항목
D9: * | E9: 회색 - 자동입력
D10: 1 | E10: Dropdown menu 에서 project를 선택하면 B1의 Project IO / B열 Status / C열 Project 내용이 자동으로 선택된다. - by PMO
D11: 2 | E11: Dropdown menu 에서 Name을 선택하면 D열/E열/F열의 내용이 자동으로 선택된다. - by functions or PMO
D12: 3 | E12: Gate5/Gate6 일정을 기재한다. (년/월 기재) - by PMO
D13: 4 | E13: 월별 HC를 입력한다. - by functions
D14: 5 | E14: 마지막 라인에 전체 project Gate plan 일정을 입력한다. 예) G1, G2….. - by PMO
B38: 2. Summary Sheet 설명
C39: A | D39: SheetMerge | F39: Do Not Change Anything | G39: 입력한 project sheet의 모든 값들이 자동으로 통합되는 database sheet
C40: B | D40: P1_정원 | F40: Pivot Sheet | G40: The number of available HC
C41: C | D41: P2_부서 | F41: Pivot Sheet | G41: 정원 대비 forecast demand 차이
C42: D | D42: P3_PRJ | F42: Pivot Sheet | G42: 프로젝트 별 forecast 현황
C43: F | D43: P3_PRJ engineer gap | F43: Pivot Sheet | G43: Project allocation 별 engineer resource gap
C44: E | D44: P4_Name | F44: Pivot Sheet | G44: 부서별 allocation 현황
C45: G | D45: Project IO | F45: Owner only allows changes | G45: Owner - Jinney L | I45: Project status / IO list
C46: H | D46: 정원 | F46: Owner only allows changes | G46: Owner - Jinney L / Mogen S / Dorothy N | K46: IS 총인원
B55: 99. Revision Note
C56: Ver. | E56: Date | F56: Description
C57: V1 | E57: 45853 | F57: 양식 변경
C58: V1.1 | E58: 45853 | F58: Excel Error 복구
C59: V1.2 | E59: 45861 | F59: PJT Lifecycle

Sheet Temp. V00
B1: =IF($A$1=0,"",VLOOKUP(A1,'Project IO'!$B$4:$C$101,2,FALSE)) | D1: 자동입력 | E1: Resource Plan | F1: Ver. | G1: 0 | H1: Date | I1: 45847 | J1: SUM | K1: =SUM(K3:K1048576) -> 0 | L1: =SUM(L3:L1048576) -> 0 | M1: =SUM(M3:M1048576) -> 0 | N1: =SUM(N3:N1048576) -> 0 | O1: =SUM(O3:O1048576) -> 0 | P1: =SUM(P3:P1048576) -> 0 | Q1: =SUM(Q3:Q1048576) -> 0 | R1: =SUM(R3:R1048576) -> 0 | ... BA1: =SUM(BA3:BA1048576) -> 0
A2: No | B2: Status | C2: PJT Lifecycle | D2: Project | E2: Resource Department | F2: Sub-Team | G2: Resource Role | H2: Name | I2: G5 | J2: G6 | K2: 45833 | L2: 45863 | M2: 45894 | N2: 45925 | O2: 45955 | P2: 45986 | Q2: 46016 | R2: 45683 | S2: 45714 | T2: 45742 | U2: 45773 | V2: 45803 | W2: 45834 | X2: 45864 | Y2: 45895 | Z2: 45926 | AA2: 45956 | AB2: 45987 | AC2: 46017 | AD2: 45684 | AE2: 45715 | AF2: 45743 | AG2: 45774 | AH2: 45804 | AI2: 45835 | AJ2: 45865 | AK2: 45896 | AL2: 45927 | AM2: 45957 | AN2: 45988 | AO2: 46018 | AP2: 45685 | AQ2: 45716 | AR2: 45744 | AS2: 45775 | AT2: 45805 | AU2: 45836 | AV2: 45866 | AW2: 45897 | AX2: 45928 | AY2: 45958 | AZ2: 45989 | BA2: 46019
A3: 1 | B3: =IF($D3=0,"",VLOOKUP($D3,'Project IO'!$B:$E,3,FALSE)) | C3: =IF($D3=0,"",VLOOKUP($D3,'Project IO'!$B:$E,4,FALSE)) | D3: =$A$1 -> 0 | E3: =IF($H3=0,"",VLOOKUP($H3,정원!$D:$G,2,FALSE)) -> Engineering | F3: =IF($H3=0,"",VLOOKUP($H3,정원!$D:$G,3,FALSE)) -> * Manager | G3: =IF($H3=0,"",VLOOKUP($H3,정원!$D:$G,4,FALSE)) -> * Eng Manager | H3: JiYoung Son
A4: 2 | B4: =IF($D4=0,"",VLOOKUP($D4,'Project IO'!$B:$E,3,FALSE)) | C4: =IF($D4=0,"",VLOOKUP($D4,'Project IO'!$B:$E,4,FALSE)) | D4: =$A$1 -> 0 | E4: =IF($H4=0,"",VLOOKUP($H4,정원!$D:$G,2,FALSE)) -> PMO | F4: =IF($H4=0,"",VLOOKUP($H4,정원!$D:$G,3,FALSE)) -> * Manager | G4: =IF($H4=0,"",VLOOKUP($H4,정원!$D:$G,4,FALSE)) -> * Manager | H4: Jinney Lee
A5: 3 | B5: =IF($D5=0,"",VLOOKUP($D5,'Project IO'!$B:$E,3,FALSE)) | C5: =IF($D5=0,"",VLOOKUP($D5,'Project IO'!$B:$E,4,FALSE)) | D5: =$A$1 -> 0 | E5: =IF($H5=0,"",VLOOKUP($H5,정원!$D:$G,2,FALSE)) -> PMO | F5: =IF($H5=0,"",VLOOKUP($H5,정원!$D:$G,3,FALSE)) -> PM | G5: =IF($H5=0,"",VLOOKUP($H5,정원!$D:$G,4,FALSE)) -> PM | H5: Project manager
A6: 4 | B6: =IF($D6=0,"",VLOOKUP($D6,'Project IO'!$B:$E,3,FALSE)) | C6: =IF($D6=0,"",VLOOKUP($D6,'Project IO'!$B:$E,4,FALSE)) | D6: =$A$1 -> 0 | E6: =IF($H6=0,"",VLOOKUP($H6,정원!$D:$G,2,FALSE)) -> NPI IS | F6: =IF($H6=0,"",VLOOKUP($H6,정원!$D:$G,3,FALSE)) -> * Manager | G6: =IF($H6=0,"",VLOOKUP($H6,정원!$D:$G,4,FALSE)) -> * Manager | H6: Dorothy Noh
A7: 5 | B7: =IF($D7=0,"",VLOOKUP($D7,'Project IO'!$B:$E,3,FALSE)) | C7: =IF($D7=0,"",VLOOKUP($D7,'Project IO'!$B:$E,4,FALSE)) | D7: =$A$1 -> 0 | E7: =IF($H7=0,"",VLOOKUP($H7,정원!$D:$G,2,FALSE)) -> NPI IS | F7: =IF($H7=0,"",VLOOKUP($H7,정원!$D:$G,3,FALSE)) -> System □ | G7: =IF($H7=0,"",VLOOKUP($H7,정원!$D:$G,4,FALSE)) -> Leader | H7: Tech Lead
A8: 6 | B8: =IF($D8=0,"",VLOOKUP($D8,'Project IO'!$B:$E,3,FALSE)) | C8: =IF($D8=0,"",VLOOKUP($D8,'Project IO'!$B:$E,4,FALSE)) | D8: =$A$1 -> 0 | E8: =IF($H8=0,"",VLOOKUP($H8,정원!$D:$G,2,FALSE)) -> NPI IS | F8: =IF($H8=0,"",VLOOKUP($H8,정원!$D:$G,3,FALSE)) -> System □ | G8: =IF($H8=0,"",VLOOKUP($H8,정원!$D:$G,4,FALSE)) -> System engineer | H8: System engineer
A9: 7 | B9: =IF($D9=0,"",VLOOKUP($D9,'Project IO'!$B:$E,3,FALSE)) | C9: =IF($D9=0,"",VLOOKUP($D9,'Project IO'!$B:$E,4,FALSE)) | D9: =$A$1 -> 0 | E9: =IF($H9=0,"",VLOOKUP($H9,정원!$D:$G,2,FALSE)) -> NPI IS | F9: =IF($H9=0,"",VLOOKUP($H9,정원!$D:$G,3,FALSE)) -> System □ | G9: =IF($H9=0,"",VLOOKUP($H9,정원!$D:$G,4,FALSE)) -> Service engineer | H9: Service engineer
A10: 8 | B10: =IF($D10=0,"",VLOOKUP($D10,'Project IO'!$B:$E,3,FALSE)) | C10: =IF($D10=0,"",VLOOKUP($D10,'Project IO'!$B:$E,4,FALSE)) | D10: =$A$1 -> 0 | E10: =IF($H10=0,"",VLOOKUP($H10,정원!$D:$G,2,FALSE)) -> NPI IS | F10: =IF($H10=0,"",VLOOKUP($H10,정원!$D:$G,3,FALSE)) -> Mechanical | G10: =IF($H10=0,"",VLOOKUP($H10,정원!$D:$G,4,FALSE)) -> Leader | H10: Jeremy Park
A11: 9 | B11: =IF($D11=0,"",VLOOKUP($D11,'Project IO'!$B:$E,3,FALSE)) | C11: =IF($D11=0,"",VLOOKUP($D11,'Project IO'!$B:$E,4,FALSE)) | D11: =$A$1 -> 0 | E11: =IF($H11=0,"",VLOOKUP($H11,정원!$D:$G,2,FALSE)) -> NPI IS | F11: =IF($H11=0,"",VLOOKUP($H11,정원!$D:$G,3,FALSE)) -> Mechanical | G11: =IF($H11=0,"",VLOOKUP($H11,정원!$D:$G,4,FALSE)) -> Mechanical engineer | H11: Mechanical engineer
A12: 10 | B12: =IF($D12=0,"",VLOOKUP($D12,'Project IO'!$B:$E,3,FALSE)) | C12: =IF($D12=0,"",VLOOKUP($D12,'Project IO'!$B:$E,4,FALSE)) | D12: =$A$1 -> 0 | E12: =IF($H12=0,"",VLOOKUP($H12,정원!$D:$G,2,FALSE)) -> Control Eng. | F12: =IF($H12=0,"",VLOOKUP($H12,정원!$D:$G,3,FALSE)) -> * Manager | G12: =IF($H12=0,"",VLOOKUP($H12,정원!$D:$G,4,FALSE)) -> * Manager | H12: Mogen Seo
A13: 11 | B13: =IF($D13=0,"",VLOOKUP($D13,'Project IO'!$B:$E,3,FALSE)) | C13: =IF($D13=0,"",VLOOKUP($D13,'Project IO'!$B:$E,4,FALSE)) | D13: =$A$1 -> 0 | E13: =IF($H13=0,"",VLOOKUP($H13,정원!$D:$G,2,FALSE)) -> Control Eng. | F13: =IF($H13=0,"",VLOOKUP($H13,정원!$D:$G,3,FALSE)) -> Software | G13: =IF($H13=0,"",VLOOKUP($H13,정원!$D:$G,4,FALSE)) -> Leader | H13: Gerald Park
A14: 12 | B14: =IF($D14=0,"",VLOOKUP($D14,'Project IO'!$B:$E,3,FALSE)) | C14: =IF($D14=0,"",VLOOKUP($D14,'Project IO'!$B:$E,4,FALSE)) | D14: =$A$1 -> 0 | E14: =IF($H14=0,"",VLOOKUP($H14,정원!$D:$G,2,FALSE)) -> Control Eng. | F14: =IF($H14=0,"",VLOOKUP($H14,정원!$D:$G,3,FALSE)) -> Software | G14: =IF($H14=0,"",VLOOKUP($H14,정원!$D:$G,4,FALSE)) -> Software engineer | H14: Software engineer
... A17: 15 | B17: =IF($D17=0,"",VLOOKUP($D17,'Project IO'!$B:$E,3,FALSE)) | C17: =IF($D17=0,"",VLOOKUP($D17,'Project IO'!$B:$E,4,FALSE)) | D17: =$A$1 -> 0 | E17: =IF($H17=0,"",VLOOKUP($H17,정원!$D:$G,2,FALSE)) -> Control Eng. | F17: =IF($H17=0,"",VLOOKUP($H17,정원!$D:$G,3,FALSE)) -> Electrical | G17: =IF($H17=0,"",VLOOKUP($H17,정원!$D:$G,4,FALSE)) -> Electrical engineer | H17: Electrical engineer
A18: 16 | B18: =IF($D18=0,"",VLOOKUP($D18,'Project IO'!$B:$E,3,FALSE)) | C18: =IF($D18=0,"",VLOOKUP($D18,'Project IO'!$B:$E,4,FALSE)) | D18: =$A$1 -> 0 | E18: =IF($H21=0,"",VLOOKUP($H21,정원!$D:$G,2,FALSE)) -> 0 | F18: =IF($H21=0,"",VLOOKUP($H21,정원!$D:$G,3,FALSE)) -> 0 | G18: =IF($H21=0,"",VLOOKUP($H21,정원!$D:$G,4,FALSE)) -> 0
A19: 17 | B19: =IF($D19=0,"",VLOOKUP($D19,'Project IO'!$B:$E,3,FALSE)) | C19: =IF($D19=0,"",VLOOKUP($D19,'Project IO'!$B:$E,4,FALSE)) | D19: =$A$1 -> 0 | E19: =IF($H22=0,"",VLOOKUP($H22,정원!$D:$G,2,FALSE)) | F19: =IF($H22=0,"",VLOOKUP($H22,정원!$D:$G,3,FALSE)) | G19: =IF($H22=0,"",VLOOKUP($H22,정원!$D:$G,4,FALSE))
A20: 18 | B20: =IF($D20=0,"",VLOOKUP($D20,'Project IO'!$B:$E,3,FALSE)) | C20: =IF($D20=0,"",VLOOKUP($D20,'Project IO'!$B:$E,4,FALSE)) | D20: =$A$1 -> 0 | E20: =IF($H23=0,"",VLOOKUP($H23,정원!$D:$G,2,FALSE)) | F20: =IF($H23=0,"",VLOOKUP($H23,정원!$D:$G,3,FALSE)) | G20: =IF($H23=0,"",VLOOKUP($H23,정원!$D:$G,4,FALSE))
A21: 19 | B21: =IF($D21=0,"",VLOOKUP($D21,'Project IO'!$B:$E,3,FALSE)) | C21: =IF($D21=0,"",VLOOKUP($D21,'Project IO'!$B:$E,4,FALSE)) | D21: =$A$1 -> 0 | E21: =IF($H24=0,"",VLOOKUP($H24,정원!$D:$G,2,FALSE)) | F21: =IF($H24=0,"",VLOOKUP($H24,정원!$D:$G,3,FALSE)) | G21: =IF($H24=0,"",VLOOKUP($H24,정원!$D:$G,4,FALSE)) | H21: Gate Plan | K21: G2 | N21: G5 | P21: G6

Sheet SheetMerge
A1: No | B1: Status | C1: PJT Lifecycle | D1: Project | E1: Resource Department | F1: Sub-Team | G1: Resource Role | H1: Name | I1: G5 | J1: G6 | K1: 45833 | L1: 45863 | M1: 45894 | N1: 45925 | O1: 45955 | P1: 45986 | Q1: 46016 | R1: 45683 | S1: 45714 | T1: 45742 | U1: 45773 | V1: 45803 | W1: 45834 | X1: 45864 | Y1: 45895 | Z1: 45926 | AA1: 45956 | AB1: 45987 | AC1: 46017 | AD1: 45684 | AE1: 45715 | AF1: 45743 | AG1: 45774 | AH1: 45804 | AI1: 45835 | AJ1: 45865 | AK1: 45896 | AL1: 45927 | AM1: 45957 | AN1: 45988 | AO1: 46018 | AP1: 45685 | AQ1: 45716 | AR1: 45744 | AS1: 45775 | AT1: 45805 | AU1: 45836 | AV1: 45866 | AW1: 45897 | AX1: 45928 | AY1: 45958 | AZ1: 45989 | BA1: 46019
A2: {=_xlfn.LET(_xlpm.취합,_xlfn.VSTACK('>:<'!A3:BA87),_xlfn._xlws.FILTER(_xlpm.취합,_xlfn.CHOOSECOLS(_xlpm.취합,1)<>""))} -> 1 | B2: Active | C2: Planning | D2: Ganymede support - PCCA | E2: NPI IS | F2: System □ | G2: System engineer | H2: System engineer | I2: 0 | J2: 0 | K2: 0 | L2: 0 | M2: 0 | N2: 0 | O2: 0 | P2: 0 | Q2: 0 | R2: 0 | S2: 0 | T2: 0 | U2: 0 | V2: 0 | W2: 0 | X2: 0 | Y2: 0 | Z2: 0 | AA2: 0 | AB2: 0 | AC2: 0 | AD2: 0 | AE2: 0 | AF2: 0 | AG2: 0 | AH2: 0 | AI2: 0 | AJ2: 0 | AK2: 0 | AL2: 0 | AM2: 0 | AN2: 0 | AO2: 0 | AP2: 0 | AQ2: 0 | AR2: 0 | AS2: 0 | AT2: 0 | AU2: 0 | AV2: 0 | AW2: 0 | AX2: 0 | AY2: 0 | AZ2: 0 | BA2: 0
A3: 2 | B3: Active | C3: Complete | D3: R&D General - Legacy/TSG | E3: Control Eng. | F3: Software | G3: Software engineer | H3: Ashley Yun | I3: 0 | J3: 0 | K3: 0 | L3: 0.3 | M3: 1 | N3: 1 | O3: 1 | P3: 0 | Q3: 0 | R3: 0 | S3: 0 | T3: 0 | U3: 0 | V3: 0 | W3: 0 | X3: 0 | Y3: 0 | Z3: 0 | AA3: 0 | AB3: 0 | AC3: 0 | AD3: 0 | AE3: 0 | AF3: 0.5 | AG3: 0.5 | AH3: 0.5 | AI3: 0.5 | AJ3: 0.5 | AK3: 0.5 | AL3: 0.5 | AM3: 0.5 | AN3: 0.5 | AO3: 0.5 | AP3: 0.5 | AQ3: 0.5 | AR3: 0.5 | AS3: 0.5 | AT3: 0.5 | AU3: 0.5 | AV3: 0.5 | AW3: 0 | AX3: 0 | AY3: 0 | AZ3: 0 | BA3: 0
A4: 3 | B4: Active | C4: Complete | D4: R&D General - Legacy/TSG | E4: Control Eng. | F4: Software | G4: Software engineer | H4: Rachel Bae | I4: 0 | J4: 0 | K4: 1 | L4: 1 | M4: 1 | N4: 1 | O4: 0.5 | P4: 0.5 | Q4: 0.5 | R4: 0.5 | S4: 0.5 | T4: 0.5 | U4: 0.5 | V4: 0.5 | W4: 1 | X4: 1 | Y4: 1 | Z4: 1 | AA4: 1 | AB4: 1 | AC4: 1 | AD4: 1 | AE4: 1 | AF4: 0.5 | AG4: 0.5 | AH4: 0.5 | AI4: 0.5 | AJ4: 0.5 | AK4: 0.5 | AL4: 0.5 | AM4: 0.5 | AN4: 0.5 | AO4: 0.5 | AP4: 0.5 | AQ4: 0.5 | AR4: 0.5 | AS4: 0.5 | AT4: 0.5 | AU4: 0.5 | AV4: 0.5 | AW4: 0 | AX4: 0 | AY4: 0 | AZ4: 0 | BA4: 0
A5: 4 | B5: Active | C5: Complete | D5: R&D General - Legacy/TSG | E5: Control Eng. | F5: Software | G5: SW test engineer | H5: Amelia An | I5: 0 | J5: 0 | K5: 1 | L5: 1 | M5: 0.9 | N5: 0.7 | O5: 0.5 | P5: 0.5 | Q5: 0.5 | R5: 0.5 | S5: 0.5 | T5: 0.5 | U5: 0.5 | V5: 0.5 | W5: 0.5 | X5: 0.5 | Y5: 0.5 | Z5: 0.5 | AA5: 0.5 | AB5: 0.5 | AC5: 0.5 | AD5: 0.5 | AE5: 0.5 | AF5: 0.5 | AG5: 0.5 | AH5: 0.5 | AI5: 0.5 | AJ5: 0.5 | AK5: 0.5 | AL5: 0.5 | AM5: 0.5 | AN5: 0.5 | AO5: 0.5 | AP5: 0.5 | AQ5: 0.5 | AR5: 0.5 | AS5: 0.5 | AT5: 0.5 | AU5: 0.5 | AV5: 0.5 | AW5: 0 | AX5: 0 | AY5: 0 | AZ5: 0 | BA5: 0
A6: 5 | B6: Active | C6: Complete | D6: R&D General - Legacy/TSG | E6: Control Eng. | F6: Software | G6: Software engineer | H6: Roy Choi | I6: 0 | J6: 0 | K6: 0.5 | L6: 0.5 | M6: 0.5 | N6: 0.5 | O6: 0.5 | P6: 1 | Q6: 1 | R6: 1 | S6: 1 | T6: 1 | U6: 1 | V6: 1 | W6: 0.5 | X6: 0.5 | Y6: 0.5 | Z6: 0.5 | AA6: 0.5 | AB6: 0.5 | AC6: 0.5 | AD6: 0.5 | AE6: 0.5 | AF6: 0.5 | AG6: 0.5 | AH6: 0.5 | AI6: 0.5 | AJ6: 0.5 | AK6: 0.5 | AL6: 0.5 | AM6: 0.5 | AN6: 0.5 | AO6: 0.5 | AP6: 0.5 | AQ6: 0.5 | AR6: 0.5 | AS6: 0.5 | AT6: 0.5 | AU6: 0.5 | AV6: 0.5 | AW6: 0 | AX6: 0 | AY6: 0 | AZ6: 0 | BA6: 0
A7: 6 | B7: Active | C7: Planning | D7: Unify support | E7: Control Eng. | F7: Software | G7: Leader | H7: Gerald Park | I7: 0 | J7: 0 | K7: 0.3 | L7: 0.3 | M7: 0.3 | N7: 0.3 | O7: 0.5 | P7: 0.5 | Q7: 0.5 | R7: 0.5 | S7: 0.5 | T7: 0.5 | U7: 0.5 | V7: 0.5 | W7: 0.3 | X7: 0.3 | Y7: 0.3 | Z7: 0.3 | AA7: 0.3 | AB7: 0.3 | AC7: 0.3 | AD7: 0.3 | AE7: 0.3 | AF7: 0.3 | AG7: 0.3 | AH7: 0.3 | AI7: 0.3 | AJ7: 0.3 | AK7: 0.3 | AL7: 0.3 | AM7: 0.3 | AN7: 0.3 | AO7: 0.3 | AP7: 0.3 | AQ7: 0.3 | AR7: 0.3 | AS7: 0.3 | AT7: 0.3 | AU7: 0.3 | AV7: 0.3 | AW7: 0 | AX7: 0 | AY7: 0 | AZ7: 0 | BA7: 0
A8: 7 | B8: Active | C8: Planning | D8: Unify support | E8: Control Eng. | F8: Software | G8: Software engineer | H8: Rachel Bae | I8: 0 | J8: 0 | K8: 0 | L8: 0 | M8: 0 | N8: 0 | O8: 0.5 | P8: 0.5 | Q8: 0.5 | R8: 0.5 | S8: 0.5 | T8: 0.5 | U8: 0.5 | V8: 0.5 | W8: 0 | X8: 0 | Y8: 0 | Z8: 0 | AA8: 0 | AB8: 0 | AC8: 0 | AD8: 0 | AE8: 0 | AF8: 0 | AG8: 0 | AH8: 0 | AI8: 0 | AJ8: 0 | AK8: 0 | AL8: 0 | AM8: 0 | AN8: 0 | AO8: 0 | AP8: 0 | AQ8: 0 | AR8: 0 | AS8: 0 | AT8: 0 | AU8: 0 | AV8: 0 | AW8: 0 | AX8: 0 | AY8: 0 | AZ8: 0 | BA8: 0
A9: 8 | B9: Active | C9: Planning | D9: Unify support | E9: Control Eng. | F9: Software | G9: SW test engineer | H9: Amelia An | I9: 0 | J9: 0 | K9: 0 | L9: 0 | M9: 0.1 | N9: 0.3 | O9: 0.5 | P9: 0.5 | Q9: 0.5 | R9: 0.5 | S9: 0.5 | T9: 0.5 | U9: 0.5 | V9: 0.5 | W9: 0.5 | X9: 0.5 | Y9: 0.5 | Z9: 0.5 | AA9: 0.5 | AB9: 0.5 | AC9: 0.5 | AD9: 0.5 | AE9: 0.5 | AF9: 0.5 | AG9: 0.5 | AH9: 0.5 | AI9: 0.5 | AJ9: 0.5 | AK9: 0.5 | AL9: 0.5 | AM9: 0.5 | AN9: 0.5 | AO9: 0.5 | AP9: 0.5 | AQ9: 0.5 | AR9: 0.5 | AS9: 0.5 | AT9: 0.5 | AU9: 0.5 | AV9: 0.5 | AW9: 0 | AX9: 0 | AY9: 0 | AZ9: 0 | BA9: 0
A10: 9 | B10: Active | C10: Complete | D10: R&D General - Legacy/TSG | E10: NPI IS | F10: System 1 | G10: Technician | H10: Robin Park | I10: 0 | J10: 0 | K10: 0.2 | L10: 0.2 | M10: 0.2 | N10: 0.2 | O10: 0 | P10: 0 | Q10: 0 | R10: 0 | S10: 0 | T10: 0 | U10: 0 | V10: 0 | W10: 0 | X10: 0 | Y10: 0 | Z10: 0 | AA10: 0 | AB10: 0 | AC10: 0 | AD10: 0 | AE10: 0 | AF10: 0 | AG10: 0 | AH10: 0 | AI10: 0 | AJ10: 0 | AK10: 0 | AL10: 0 | AM10: 0 | AN10: 0 | AO10: 0 | AP10: 0 | AQ10: 0 | AR10: 0 | AS10: 0 | AT10: 0 | AU10: 0 | AV10: 0 | AW10: 0 | AX10: 0 | AY10: 0 | AZ10: 0 | BA10: 0
A11: 10 | B11: Active | C11: Lead | D11: CatOX Alpha design | E11: NPI IS | F11: Mechanical | G11: Mechanical engineer | H11: Jiny Park | I11: 0 | J11: 0 | K11: 0 | L11: 1 | M11: 1 | N11: 0.5 | O11: 0.5 | P11: 0.5 | Q11: 0 | R11: 0 | S11: 0 | T11: 0 | U11: 0 | V11: 0 | W11: 0 | X11: 0 | Y11: 0 | Z11: 0 | AA11: 0 | AB11: 0 | AC11: 0 | AD11: 0 | AE11: 0 | AF11: 0 | AG11: 0 | AH11: 0 | AI11: 0 | AJ11: 0 | AK11: 0 | AL11: 0 | AM11: 0 | AN11: 0 | AO11: 0 | AP11: 0 | AQ11: 0 | AR11: 0 | AS11: 0 | AT11: 0 | AU11: 0 | AV11: 0 | AW11: 0 | AX11: 0 | AY11: 0 | AZ11: 0 | BA11: 0
A12: 11 | B12: Cancelled | C12: Cancelled | D12: Hermes | E12: Control Eng. | F12: Software | G12: Software engineer | H12: Roy Choi | I12: 0 | J12: 0 | K12: 0 | L12: 0 | M12: 0 | N12: 0 | O12: 0 | P12: 0 | Q12: 0 | R12: 0 | S12: 0 | T12: 0 | U12: 0 | V12: 0 | W12: 0 | X12: 0 | Y12: 0 | Z12: 0 | AA12: 0 | AB12: 0 | AC12: 0 | AD12: 0 | AE12: 0 | AF12: 0 | AG12: 0 | AH12: 0 | AI12: 0 | AJ12: 0 | AK12: 0 | AL12: 0 | AM12: 0 | AN12: 0 | AO12: 0 | AP12: 0 | AQ12: 0 | AR12: 0 | AS12: 0 | AT12: 0 | AU12: 0 | AV12: 0 | AW12: 0 | AX12: 0 | AY12: 0 | AZ12: 0 | BA12: 0
A13: 12 | B13: Cancelled | C13: Cancelled | D13: Hermes | E13: Control Eng. | F13: Software | G13: SW test engineer | H13: Moonsu Cho | I13: 0 | J13: 0 | K13: 0 | L13: 0 | M13: 0 | N13: 0 | O13: 0 | P13: 0 | Q13: 0 | R13: 0 | S13: 0 | T13: 0 | U13: 0 | V13: 0 | W13: 0 | X13: 0 | Y13: 0 | Z13: 0 | AA13: 0 | AB13: 0 | AC13: 0 | AD13: 0 | AE13: 0 | AF13: 0 | AG13: 0 | AH13: 0 | AI13: 0 | AJ13: 0 | AK13: 0 | AL13: 0 | AM13: 0 | AN13: 0 | AO13: 0 | AP13: 0 | AQ13: 0 | AR13: 0 | AS13: 0 | AT13: 0 | AU13: 0 | AV13: 0 | AW13: 0 | AX13: 0 | AY13: 0 | AZ13: 0 | BA13: 0
A14: 13 | B14: Active | C14: Active | D14: LPLN TOP 150 support | E14: NPI IS | F14: System 3 | G14: Tech Lead | H14: Grace Ji | I14: 0 | J14: 0 | K14: 0 | L14: 0 | M14: 0 | N14: 0 | O14: 0.5 | P14: 1 | Q14: 1 | R14: 1 | S14: 1 | T14: 1 | U14: 1 | V14: 1 | W14: 1 | X14: 1 | Y14: 1 | Z14: 1 | AA14: 1 | AB14: 1 | AC14: 1 | AD14: 0 | AE14: 0 | AF14: 0 | AG14: 0 | AH14: 0 | AI14: 0 | AJ14: 0 | AK14: 0 | AL14: 0 | AM14: 0 | AN14: 0 | AO14: 0 | AP14: 0 | AQ14: 0 | AR14: 0 | AS14: 0 | AT14: 0 | AU14: 0 | AV14: 0 | AW14: 0 | AX14: 0 | AY14: 0 | AZ14: 0 | BA14: 0
... A38: 22 | B38: Active | C38: Active | D38: Micron A&D | E38: NPI IS | F38: System 2 | G38: System engineer | H38: Kevin Ko | I38: 45742 | J38: 45742 | K38: 0 | L38: 0 | M38: 0 | N38: 0 | O38: 0 | P38: 0.5 | Q38: 0 | R38: 0 | S38: 0 | T38: 0 | U38: 0 | V38: 0 | W38: 0 | X38: 0 | Y38: 0 | Z38: 0 | AA38: 0 | AB38: 0 | AC38: 0 | AD38: 0 | AE38: 0 | AF38: 0 | AG38: 0 | AH38: 0 | AI38: 0 | AJ38: 0 | AK38: 0 | AL38: 0 | AM38: 0 | AN38: 0 | AO38: 0 | AP38: 0 | AQ38: 0 | AR38: 0 | AS38: 0 | AT38: 0 | AU38: 0 | AV38: 0 | AW38: 0 | AX38: 0 | AY38: 0 | AZ38: 0 | BA38: 0
A39: 23 | B39: Active | C39: Active | D39: Micron A&D | E39: 0 | F39: 0 | G39: 0 | H39: Gate Plan | I39: 45742 | J39: 45742 | K39: 0 | L39: Update | M39: 0 | N39: 0 | O39: 0 | P39: 0 | Q39: 0 | R39: 0 | S39: 0 | T39: G5 | U39: 0 | V39: 0 | W39: 0 | X39: G6 | Y39: 0 | Z39: 0 | AA39: 0 | AB39: 0 | AC39: 0 | AD39: 0 | AE39: 0 | AF39: 0 | AG39: 0 | AH39: 0 | AI39: 0 | AJ39: 0 | AK39: 0 | AL39: 0 | AM39: 0 | AN39: 0 | AO39: 0 | AP39: 0 | AQ39: 0 | AR39: 0 | AS39: 0 | AT39: 0 | AU39: 0 | AV39: 0 | AW39: 0 | AX39: 0 | AY39: 0 | AZ39: 0 | BA39: 0
A40: 1 | B40: Active | C40: Active | D40: Tumalo Ph2 | E40: Engineering | F40: * Manager | G40: * Eng Manager | H40: Jiyoung Son | I40: 46113 | J40: 46293 | K40: 0 | L40: 0 | M40: 0 | N40: 0 | O40: 0 | P40: 0 | Q40: 0 | R40: 0.1 | S40: 0.1 | T40: 0.1 | U40: 0.1 | V40: 0.1 | W40: 0.1 | X40: 0.1 | Y40: 0.1 | Z40: 0.1 | AA40: 0.1 | AB40: 0.1 | AC40: 0.1 | AD40: 0.1 | AE40: 0.1 | AF40: 0.1 | AG40: 0.1 | AH40: 0.1 | AI40: 0.1 | AJ40: 0.1 | AK40: 0.1 | AL40: 0.1 | AM40: 0 | AN40: 0 | AO40: 0 | AP40: 0 | AQ40: 0 | AR40: 0 | AS40: 0 | AT40: 0 | AU40: 0 | AV40: 0 | AW40: 0 | AX40: 0 | AY40: 0 | AZ40: 0 | BA40: 0
A41: 2 | B41: Active | C41: Active | D41: Tumalo Ph2 | E41: PMO | F41: * Manager | G41: * Manager | H41: Jinney Lee | I41: 46113 | J41: 46293 | K41: 0 | L41: 0.3 | M41: 0.3 | N41: 0.3 | O41: 0.3 | P41: 0.3 | Q41: 0.3 | R41: 0.3 | S41: 0.3 | T41: 0.3 | U41: 0.3 | V41: 0.3 | W41: 0.3 | X41: 0.3 | Y41: 0.3 | Z41: 0.3 | AA41: 0.3 | AB41: 0.3 | AC41: 0.3 | AD41: 0.2 | AE41: 0.2 | AF41: 0.2 | AG41: 0.2 | AH41: 0.1 | AI41: 0.1 | AJ41: 0.1 | AK41: 0.1 | AL41: 0.1 | AM41: 0 | AN41: 0 | AO41: 0 | AP41: 0 | AQ41: 0 | AR41: 0 | AS41: 0 | AT41: 0 | AU41: 0 | AV41: 0 | AW41: 0 | AX41: 0 | AY41: 0 | AZ41: 0 | BA41: 0
A42: 3 | B42: Active | C42: Active | D42: Tumalo Ph2 | E42: PMO | F42: PM | G42: PM | H42: Evan Lee | I42: 46113 | J42: 46293 | K42: 0 | L42: 0.5 | M42: 0.5 | N42: 0.8 | O42: 0.8 | P42: 1 | Q42: 1 | R42: 1 | S42: 1 | T42: 1 | U42: 1 | V42: 1 | W42: 1 | X42: 1 | Y42: 1 | Z42: 1 | AA42: 1 | AB42: 1 | AC42: 1 | AD42: 1 | AE42: 1 | AF42: 1 | AG42: 1 | AH42: 0.5 | AI42: 0.5 | AJ42: 0.5 | AK42: 0.5 | AL42: 0.5 | AM42: 0 | AN42: 0 | AO42: 0 | AP42: 0 | AQ42: 0 | AR42: 0 | AS42: 0 | AT42: 0 | AU42: 0 | AV42: 0 | AW42: 0 | AX42: 0 | AY42: 0 | AZ42: 0 | BA42: 0
A43: 4 | B43: Active | C43: Active | D43: Tumalo Ph2 | E43: NPI IS | F43: * Manager | G43: * Manager | H43: Dorothy Noh | I43: 46478 | J43: 46658 | K43: 0 | L43: 0.3 | M43: 0.3 | N43: 0.3 | O43: 0.3 | P43: 0.3 | Q43: 0.3 | R43: 0.3 | S43: 0.3 | T43: 0.3 | U43: 0.3 | V43: 0.3 | W43: 0.3 | X43: 0.3 | Y43: 0.3 | Z43: 0.3 | AA43: 0.3 | AB43: 0.3 | AC43: 0.3 | AD43: 0.3 | AE43: 0.3 | AF43: 0.3 | AG43: 0.3 | AH43: 0.2 | AI43: 0.2 | AJ43: 0.2 | AK43: 0.2 | AL43: 0.2 | AM43: 0 | AN43: 0 | AO43: 0 | AP43: 0 | AQ43: 0 | AR43: 0 | AS43: 0 | AT43: 0 | AU43: 0 | AV43: 0 | AW43: 0 | AX43: 0 | AY43: 0 | AZ43: 0 | BA43: 0
A44: 5 | B44: Active | C44: Active | D44: Tumalo Ph2 | E44: NPI IS | F44: System 3 | G44: Tech Lead | H44: Jacob Lee | I44: 46478 | J44: 46658 | K44: 0 | L44: 0 | M44: 0 | N44: 0.4 | O44: 0.4 | P44: 0.4 | Q44: 0.4 | R44: 0.4 | S44: 0.4 | T44: 0.5 | U44: 0.5 | V44: 0.5 | W44: 0.5 | X44: 0.5 | Y44: 0.5 | Z44: 0.5 | AA44: 0.5 | AB44: 0.5 | AC44: 0.5 | AD44: 0.5 | AE44: 0.5 | AF44: 0.5 | AG44: 0.5 | AH44: 0.5 | AI44: 0.5 | AJ44: 0.5 | AK44: 0.5 | AL44: 0.5 | AM44: 0 | AN44: 0 | AO44: 0 | AP44: 0 | AQ44: 0 | AR44: 0 | AS44: 0 | AT44: 0 | AU44: 0 | AV44: 0 | AW44: 0 | AX44: 0 | AY44: 0 | AZ44: 0 | BA44: 0
A45: 6 | B45: Active | C45: Active | D45: Tumalo Ph2 | E45: NPI IS | F45: System 3 | G45: Tech Lead | H45: William Lee | I45: 46478 | J45: 46658 | K45: 0 | L45: 0.9 | M45: 0.9 | N45: 0.9 | O45: 0.9 | P45: 0.9 | Q45: 0.9 | R45: 0.9 | S45: 0.9 | T45: 0.9 | U45: 1 | V45: 1 | W45: 1 | X45: 1 | Y45: 1 | Z45: 1 | AA45: 1 | AB45: 1 | AC45: 1 | AD45: 1 | AE45: 1 | AF45: 1 | AG45: 1 | AH45: 1 | AI45: 1 | AJ45: 1 | AK45: 1 | AL45: 1 | AM45: 0 | AN45: 0 | AO45: 0 | AP45: 0 | AQ45: 0 | AR45: 0 | AS45: 0 | AT45: 0 | AU45: 0 | AV45: 0 | AW45: 0 | AX45: 0 | AY45: 0 | AZ45: 0 | BA45: 0
A46: 7 | B46: Active | C46: Active | D46: Tumalo Ph2 | E46: NPI IS | F46: System 2 | G46: System engineer | H46: Harry Kwak | I46: 46478 | J46: 46658 | K46: 0 | L46: 0 | M46: 0.4 | N46: 0.4 | O46: 0 | P46: 0 | Q46: 0.4 | R46: 0.5 | S46: 0.5 | T46: 0.5 | U46: 0.5 | V46: 0.5 | W46: 0.5 | X46: 0.5 | Y46: 0.5 | Z46: 0.5 | AA46: 0.5 | AB46: 0.5 | AC46: 0.5 | AD46: 1 | AE46: 1 | AF46: 1 | AG46: 1 | AH46: 1 | AI46: 1 | AJ46: 1 | AK46: 1 | AL46: 1 | AM46: 0 | AN46: 0 | AO46: 0 | AP46: 0 | AQ46: 0 | AR46: 0 | AS46: 0 | AT46: 0 | AU46: 0 | AV46: 0 | AW46: 0 | AX46: 0 | AY46: 0 | AZ46: 0 | BA46: 0
A47: 8 | B47: Active | C47: Active | D47: Tumalo Ph2 | E47: NPI IS | F47: System 3 | G47: System engineer | H47: Noah Yeom | I47: 46478 | J47: 46658 | K47: 0 | L47: 0 | M47: 0.4 | N47: 0.4 | O47: 0.4 | P47: 0.4 | Q47: 0.4 | R47: 0.4 | S47: 0.4 | T47: 0.4 | U47: 0.4 | V47: 0.4 | W47: 0.4 | X47: 0.4 | Y47: 0 | Z47: 0 | AA47: 0 | AB47: 0 | AC47: 0 | AD47: 0 | AE47: 0 | AF47: 0 | AG47: 0 | AH47: 0 | AI47: 0 | AJ47: 0 | AK47: 0 | AL47: 0 | AM47: 0 | AN47: 0 | AO47: 0 | AP47: 0 | AQ47: 0 | AR47: 0 | AS47: 0 | AT47: 0 | AU47: 0 | AV47: 0 | AW47: 0 | AX47: 0 | AY47: 0 | AZ47: 0 | BA47: 0
A48: 9 | B48: Active | C48: Active | D48: Tumalo Ph2 | E48: NPI IS | F48: System 3 | G48: System engineer | H48: Alyssa Park | I48: 46478 | J48: 46658 | K48: 0 | L48: 0 | M48: 0.4 | N48: 0.4 | O48: 0.4 | P48: 0.4 | Q48: 0.4 | R48: 0.4 | S48: 0.4 | T48: 0.4 | U48: 0.4 | V48: 0.4 | W48: 0.4 | X48: 0.4 | Y48: 0 | Z48: 0 | AA48: 0 | AB48: 0 | AC48: 0 | AD48: 0 | AE48: 0 | AF48: 0 | AG48: 0 | AH48: 0 | AI48: 0 | AJ48: 0 | AK48: 0 | AL48: 0 | AM48: 0 | AN48: 0 | AO48: 0 | AP48: 0 | AQ48: 0 | AR48: 0 | AS48: 0 | AT48: 0 | AU48: 0 | AV48: 0 | AW48: 0 | AX48: 0 | AY48: 0 | AZ48: 0 | BA48: 0
A49: 10 | B49: Active | C49: Active | D49: Tumalo Ph2 | E49: NPI IS | F49: System 1 | G49: System engineer | H49: Anders You | I49: 46478 | J49: 46658 | K49: 0 | L49: 0 | M49: 0 | N49: 0.5 | O49: 0.5 | P49: 0.5 | Q49: 0.5 | R49: 0.5 | S49: 0.5 | T49: 0.5 | U49: 0.5 | V49: 0.5 | W49: 0.5 | X49: 0.5 | Y49: 1 | Z49: 1 | AA49: 1 | AB49: 1 | AC49: 1 | AD49: 1 | AE49: 1 | AF49: 1 | AG49: 1 | AH49: 1 | AI49: 1 | AJ49: 1 | AK49: 1 | AL49: 1 | AM49: 0 | AN49: 0 | AO49: 0 | AP49: 0 | AQ49: 0 | AR49: 0 | AS49: 0 | AT49: 0 | AU49: 0 | AV49: 0 | AW49: 0 | AX49: 0 | AY49: 0 | AZ49: 0 | BA49: 0
A50: 11 | B50: Active | C50: Active | D50: Tumalo Ph2 | E50: NPI IS | F50: System 3 | G50: Service engineer | H50: Fred Lee | I50: 46478 | J50: 46658 | K50: 0 | L50: 0 | M50: 0.4 | N50: 0.4 | O50: 0.4 | P50: 0.4 | Q50: 0.4 | R50: 0.4 | S50: 0.4 | T50: 0.4 | U50: 0.4 | V50: 0.4 | W50: 0.4 | X50: 0.4 | Y50: 1 | Z50: 1 | AA50: 1 | AB50: 1 | AC50: 1 | AD50: 1 | AE50: 1 | AF50: 1 | AG50: 1 | AH50: 1 | AI50: 1 | AJ50: 1 | AK50: 1 | AL50: 1 | AM50: 0 | AN50: 0 | AO50: 0 | AP50: 0 | AQ50: 0 | AR50: 0 | AS50: 0 | AT50: 0 | AU50: 0 | AV50: 0 | AW50: 0 | AX50: 0 | AY50: 0 | AZ50: 0 | BA50: 0
A51: 12 | B51: Active | C51: Active | D51: Tumalo Ph2 | E51: NPI IS | F51: System 1 | G51: Service engineer | H51: Chan Hwang | I51: 46478 | J51: 46658 | K51: 0 | L51: 0 | M51: 0.4 | N51: 0.4 | O51: 0.5 | P51: 0 | Q51: 0 | R51: 0 | S51: 0 | T51: 0 | U51: 0 | V51: 0 | W51: 0 | X51: 0 | Y51: 0 | Z51: 0 | AA51: 0 | AB51: 0 | AC51: 0 | AD51: 0 | AE51: 0 | AF51: 0 | AG51: 0 | AH51: 0 | AI51: 0 | AJ51: 0 | AK51: 0 | AL51: 0 | AM51: 0 | AN51: 0 | AO51: 0 | AP51: 0 | AQ51: 0 | AR51: 0 | AS51: 0 | AT51: 0 | AU51: 0 | AV51: 0 | AW51: 0 | AX51: 0 | AY51: 0 | AZ51: 0 | BA51: 0
... A70: 30 | B70: Active | C70: Active | D70: Tumalo Ph2 | E70: Control Eng. | F70: Electrical | G70: Electrical engineer | H70: Andy Jang | I70: 46478 | J70: 46658 | K70: 0 | L70: 0 | M70: 0 | N70: 0.5 | O70: 0.5 | P70: 0.5 | Q70: 0.5 | R70: 1 | S70: 1 | T70: 1 | U70: 1 | V70: 1 | W70: 1 | X70: 1 | Y70: 1 | Z70: 1 | AA70: 1 | AB70: 1 | AC70: 1 | AD70: 1 | AE70: 1 | AF70: 1 | AG70: 1 | AH70: 1 | AI70: 1 | AJ70: 1 | AK70: 1 | AL70: 1 | AM70: 0 | AN70: 0 | AO70: 0 | AP70: 0 | AQ70: 0 | AR70: 0 | AS70: 0 | AT70: 0 | AU70: 0 | AV70: 0 | AW70: 0 | AX70: 0 | AY70: 0 | AZ70: 0 | BA70: 0
A71: 31 | B71: Active | C71: Active | D71: Tumalo Ph2 | E71: 0 | F71: 0 | G71: 0 | H71: Gate Plan | I71: 46478 | J71: 46658 | K71: 0 | L71: G2 | M71: 0 | N71: 0 | O71: 0 | P71: 0 | Q71: 0 | R71: G3 | S71: 0 | T71: 0 | U71: 0 | V71: 0 | W71: 0 | X71: G4 | Y71: 0 | Z71: 0 | AA71: 0 | AB71: 0 | AC71: 0 | AD71: 0 | AE71: 0 | AF71: 0 | AG71: G5 | AH71: 0 | AI71: 0 | AJ71: 0 | AK71: 0 | AL71: G6 | AM71: 0 | AN71: 0 | AO71: 0 | AP71: 0 | AQ71: 0 | AR71: 0 | AS71: 0 | AT71: 0 | AU71: 0 | AV71: 0 | AW71: 0 | AX71: 0 | AY71: 0 | AZ71: 0 | BA71: 0
A72: 1 | B72: Active | C72: ETO | D72: Gen3 EUV Zenith Plus 7SRC TSMC | E72: PMO | F72: * Manager | G72: * Manager | H72: Jinney Lee | I72: 0 | J72: 0 | K72: 0 | L72: 0 | M72: 0.2 | N72: 0.2 | O72: 0.2 | P72: 0.2 | Q72: 0.2 | R72: 0 | S72: 0 | T72: 0 | U72: 0 | V72: 0 | W72: 0 | X72: 0 | Y72: 0 | Z72: 0 | AA72: 0 | AB72: 0 | AC72: 0 | AD72: 0 | AE72: 0 | AF72: 0 | AG72: 0 | AH72: 0 | AI72: 0 | AJ72: 0 | AK72: 0 | AL72: 0 | AM72: 0 | AN72: 0 | AO72: 0 | AP72: 0 | AQ72: 0 | AR72: 0 | AS72: 0 | AT72: 0 | AU72: 0 | AV72: 0 | AW72: 0 | AX72: 0 | AY72: 0 | AZ72: 0 | BA72: 0
A73: 2 | B73: Active | C73: ETO | D73: Gen3 EUV Zenith Plus 7SRC TSMC | E73: NPI IS | F73: System 2 | G73: Tech Lead | H73: Chad Seo | I73: 0 | J73: 0 | K73: 0 | L73: 0 | M73: 0 | N73: 1 | O73: 1 | P73: 1 | Q73: 0.5 | R73: 0 | S73: 0 | T73: 0 | U73: 0 | V73: 0 | W73: 0 | X73: 0 | Y73: 0 | Z73: 0 | AA73: 0 | AB73: 0 | AC73: 0 | AD73: 0 | AE73: 0 | AF73: 0 | AG73: 0 | AH73: 0 | AI73: 0 | AJ73: 0 | AK73: 0 | AL73: 0 | AM73: 0 | AN73: 0 | AO73: 0 | AP73: 0 | AQ73: 0 | AR73: 0 | AS73: 0 | AT73: 0 | AU73: 0 | AV73: 0 | AW73: 0 | AX73: 0 | AY73: 0 | AZ73: 0 | BA73: 0
A74: 3 | B74: Active | C74: ETO | D74: Gen3 EUV Zenith Plus 7SRC TSMC | E74: NPI IS | F74: * Manager | G74: * Manager | H74: Dorothy Noh | I74: 0 | J74: 0 | K74: 0 | L74: 0 | M74: 0 | N74: 0.1 | O74: 0.1 | P74: 0.1 | Q74: 0.1 | R74: 0 | S74: 0 | T74: 0 | U74: 0 | V74: 0 | W74: 0 | X74: 0 | Y74: 0 | Z74: 0 | AA74: 0 | AB74: 0 | AC74: 0 | AD74: 0 | AE74: 0 | AF74: 0 | AG74: 0 | AH74: 0 | AI74: 0 | AJ74: 0 | AK74: 0 | AL74: 0 | AM74: 0 | AN74: 0 | AO74: 0 | AP74: 0 | AQ74: 0 | AR74: 0 | AS74: 0 | AT74: 0 | AU74: 0 | AV74: 0 | AW74: 0 | AX74: 0 | AY74: 0 | AZ74: 0 | BA74: 0
A75: 5 | B75: Active | C75: ETO | D75: Gen3 EUV Zenith Plus 7SRC TSMC | E75: NPI IS | F75: System 2 | G75: System engineer | H75: Kevin Ko | I75: 0 | J75: 0 | K75: 0 | L75: 0 | M75: 0 | N75: 1 | O75: 0 | P75: 0 | Q75: 0 | R75: 0 | S75: 0 | T75: 0 | U75: 0 | V75: 0 | W75: 0 | X75: 0 | Y75: 0 | Z75: 0 | AA75: 0 | AB75: 0 | AC75: 0 | AD75: 0 | AE75: 0 | AF75: 0 | AG75: 0 | AH75: 0 | AI75: 0 | AJ75: 0 | AK75: 0 | AL75: 0 | AM75: 0 | AN75: 0 | AO75: 0 | AP75: 0 | AQ75: 0 | AR75: 0 | AS75: 0 | AT75: 0 | AU75: 0 | AV75: 0 | AW75: 0 | AX75: 0 | AY75: 0 | AZ75: 0 | BA75: 0
A76: 6 | B76: Active | C76: ETO | D76: Gen3 EUV Zenith Plus 7SRC TSMC | E76: NPI IS | F76: System 2 | G76: Service engineer | H76: Sophie Kim | I76: 0 | J76: 0 | K76: 0 | L76: 0 | M76: 0 | N76: 0.7 | O76: 0 | P76: 0 | Q76: 0 | R76: 0 | S76: 0 | T76: 0 | U76: 0 | V76: 0 | W76: 0 | X76: 0 | Y76: 0 | Z76: 0 | AA76: 0 | AB76: 0 | AC76: 0 | AD76: 0 | AE76: 0 | AF76: 0 | AG76: 0 | AH76: 0 | AI76: 0 | AJ76: 0 | AK76: 0 | AL76: 0 | AM76: 0 | AN76: 0 | AO76: 0 | AP76: 0 | AQ76: 0 | AR76: 0 | AS76: 0 | AT76: 0 | AU76: 0 | AV76: 0 | AW76: 0 | AX76: 0 | AY76: 0 | AZ76: 0 | BA76: 0
A77: 7 | B77: Active | C77: ETO | D77: Gen3 EUV Zenith Plus 7SRC TSMC | E77: NPI IS | F77: System 2 | G77: System engineer | H77: Jess Kim | I77: 0 | J77: 0 | K77: 0 | L77: 0 | M77: 0 | N77: 0 | O77: 0.5 | P77: 0.5 | Q77: 0 | R77: 0 | S77: 0 | T77: 0 | U77: 0 | V77: 0 | W77: 0 | X77: 0 | Y77: 0 | Z77: 0 | AA77: 0 | AB77: 0 | AC77: 0 | AD77: 0 | AE77: 0 | AF77: 0 | AG77: 0 | AH77: 0 | AI77: 0 | AJ77: 0 | AK77: 0 | AL77: 0 | AM77: 0 | AN77: 0 | AO77: 0 | AP77: 0 | AQ77: 0 | AR77: 0 | AS77: 0 | AT77: 0 | AU77: 0 | AV77: 0 | AW77: 0 | AX77: 0 | AY77: 0 | AZ77: 0 | BA77: 0
A78: 8 | B78: Active | C78: ETO | D78: Gen3 EUV Zenith Plus 7SRC TSMC | E78: NPI IS | F78: Mechanical | G78: Leader | H78: Jeremy Park | I78: 0 | J78: 0 | K78: 0 | L78: 0 | M78: 0 | N78: 0.1 | O78: 0.1 | P78: 0.1 | Q78: 0 | R78: 0 | S78: 0 | T78: 0 | U78: 0 | V78: 0 | W78: 0 | X78: 0 | Y78: 0 | Z78: 0 | AA78: 0 | AB78: 0 | AC78: 0 | AD78: 0 | AE78: 0 | AF78: 0 | AG78: 0 | AH78: 0 | AI78: 0 | AJ78: 0 | AK78: 0 | AL78: 0 | AM78: 0 | AN78: 0 | AO78: 0 | AP78: 0 | AQ78: 0 | AR78: 0 | AS78: 0 | AT78: 0 | AU78: 0 | AV78: 0 | AW78: 0 | AX78: 0 | AY78: 0 | AZ78: 0 | BA78: 0
A79: 9 | B79: Active | C79: ETO | D79: Gen3 EUV Zenith Plus 7SRC TSMC | E79: NPI IS | F79: Mechanical | G79: Mechanical engineer | H79: Jayden Lee | I79: 0 | J79: 0 | K79: 0 | L79: 0 | M79: 0 | N79: 0.5 | O79: 0.5 | P79: 0.5 | Q79: 0 | R79: 0 | S79: 0 | T79: 0 | U79: 0 | V79: 0 | W79: 0 | X79: 0 | Y79: 0 | Z79: 0 | AA79: 0 | AB79: 0 | AC79: 0 | AD79: 0 | AE79: 0 | AF79: 0 | AG79: 0 | AH79: 0 | AI79: 0 | AJ79: 0 | AK79: 0 | AL79: 0 | AM79: 0 | AN79: 0 | AO79: 0 | AP79: 0 | AQ79: 0 | AR79: 0 | AS79: 0 | AT79: 0 | AU79: 0 | AV79: 0 | AW79: 0 | AX79: 0 | AY79: 0 | AZ79: 0 | BA79: 0
A80: 10 | B80: Active | C80: ETO | D80: Gen3 EUV Zenith Plus 7SRC TSMC | E80: NPI IS | F80: Mechanical | G80: Mechanical engineer | H80: Derek Cho | I80: 0 | J80: 0 | K80: 0 | L80: 0 | M80: 0 | N80: 0.5 | O80: 0 | P80: 0 | Q80: 0 | R80: 0 | S80: 0 | T80: 0 | U80: 0 | V80: 0 | W80: 0 | X80: 0 | Y80: 0 | Z80: 0 | AA80: 0 | AB80: 0 | AC80: 0 | AD80: 0 | AE80: 0 | AF80: 0 | AG80: 0 | AH80: 0 | AI80: 0 | AJ80: 0 | AK80: 0 | AL80: 0 | AM80: 0 | AN80: 0 | AO80: 0 | AP80: 0 | AQ80: 0 | AR80: 0 | AS80: 0 | AT80: 0 | AU80: 0 | AV80: 0 | AW80: 0 | AX80: 0 | AY80: 0 | AZ80: 0 | BA80: 0
A81: 11 | B81: Active | C81: ETO | D81: Gen3 EUV Zenith Plus 7SRC TSMC | E81: Control Eng. | F81: * Manager | G81: * Manager | H81: Mogen Seo | I81: 0 | J81: 0 | K81: 0 | L81: 0 | M81: 0 | N81: 0 | O81: 0 | P81: 0 | Q81: 0 | R81: 0 | S81: 0 | T81: 0 | U81: 0 | V81: 0 | W81: 0 | X81: 0 | Y81: 0 | Z81: 0 | AA81: 0 | AB81: 0 | AC81: 0 | AD81: 0 | AE81: 0 | AF81: 0 | AG81: 0 | AH81: 0 | AI81: 0 | AJ81: 0 | AK81: 0 | AL81: 0 | AM81: 0 | AN81: 0 | AO81: 0 | AP81: 0 | AQ81: 0 | AR81: 0 | AS81: 0 | AT81: 0 | AU81: 0 | AV81: 0 | AW81: 0 | AX81: 0 | AY81: 0 | AZ81: 0 | BA81: 0
...

Sheet P1_정원
A1: Total IS NPI | B1: {=B12:AA12} -> 46.9 | C1: 46.9 | D1: 46.9 | E1: 45.9 | F1: 45.9 | G1: 45.9 | H1: 45.9 | I1: 45.9 | J1: 46.9 | K1: 46.9 | L1: 46.9 | M1: 46.9 | N1: 46.9 | O1: 47.9 | P1: 47.9 | Q1: 47.9 | R1: 48.9 | S1: 48.9 | T1: 48.9 | U1: 48.9 | V1: 48.9 | W1: 48.9 | X1: 48.9 | Y1: 48.9 | Z1: 48.9 | AA1: 48.9
A2: Sustaining SW | B2: =SUMIF('etc. V00'!$D$3:$D$60,"R&D General - Legacy/TSG",'etc. V00'!P3:P60) -> 2 | C2: =SUMIF('etc. V00'!$D$3:$D$60,"R&D General - Legacy/TSG",'etc. V00'!Q3:Q60) -> 2 | D2: =SUMIF('etc. V00'!$D$3:$D$60,"R&D General - Legacy/TSG",'etc. V00'!R3:R60) -> 2 | E2: =SUMIF('etc. V00'!$D$3:$D$60,"R&D General - Legacy/TSG",'etc. V00'!S3:S60) -> 2 | F2: =SUMIF('etc. V00'!$D$3:$D$60,"R&D General - Legacy/TSG",'etc. V00'!T3:T60) -> 2 | G2: =SUMIF('etc. V00'!$D$3:$D$60,"R&D General - Legacy/TSG",'etc. V00'!U3:U60) -> 2 | H2: =SUMIF('etc. V00'!$D$3:$D$60,"R&D General - Legacy/TSG",'etc. V00'!V3:V60) -> 2 | I2: =SUMIF('etc. V00'!$D$3:$D$60,"R&D General - Legacy/TSG",'etc. V00'!W3:W60) -> 2 | ... AA2: =SUMIF('etc. V00'!$D$3:$D$60,"R&D General - Legacy/TSG",'etc. V00'!AO3:AO60) -> 2
A3: Unify support SW | B3: =SUMIF('etc. V00'!$D$3:$D$60,"Unify support",'etc. V00'!P3:P60) -> 1.5 | C3: =SUMIF('etc. V00'!$D$3:$D$60,"Unify support",'etc. V00'!Q3:Q60) -> 1.5 | D3: =SUMIF('etc. V00'!$D$3:$D$60,"Unify support",'etc. V00'!R3:R60) -> 1.5 | E3: =SUMIF('etc. V00'!$D$3:$D$60,"Unify support",'etc. V00'!S3:S60) -> 1.5 | F3: =SUMIF('etc. V00'!$D$3:$D$60,"Unify support",'etc. V00'!T3:T60) -> 1.5 | G3: =SUMIF('etc. V00'!$D$3:$D$60,"Unify support",'etc. V00'!U3:U60) -> 1.5 | H3: =SUMIF('etc. V00'!$D$3:$D$60,"Unify support",'etc. V00'!V3:V60) -> 1.5 | I3: =SUMIF('etc. V00'!$D$3:$D$60,"Unify support",'etc. V00'!W3:W60) -> 0.8 | ... AA3: =SUMIF('etc. V00'!$D$3:$D$60,"Unify support",'etc. V00'!AO3:AO60) -> 0.8
A4: 파견 LPLN SE | B4: =SUMIF('etc. V00'!$D$3:$D$60,"LPLN TOP 150 support",'etc. V00'!P3:P60) -> 3 | C4: =SUMIF('etc. V00'!$D$3:$D$60,"LPLN TOP 150 support",'etc. V00'!Q3:Q60) -> 3 | D4: =SUMIF('etc. V00'!$D$3:$D$60,"LPLN TOP 150 support",'etc. V00'!R3:R60) -> 3 | E4: =SUMIF('etc. V00'!$D$3:$D$60,"LPLN TOP 150 support",'etc. V00'!S3:S60) -> 3 | F4: =SUMIF('etc. V00'!$D$3:$D$60,"LPLN TOP 150 support",'etc. V00'!T3:T60) -> 3 | G4: =SUMIF('etc. V00'!$D$3:$D$60,"LPLN TOP 150 support",'etc. V00'!U3:U60) -> 3 | H4: =SUMIF('etc. V00'!$D$3:$D$60,"LPLN TOP 150 support",'etc. V00'!V3:V60) -> 3 | I4: =SUMIF('etc. V00'!$D$3:$D$60,"LPLN TOP 150 support",'etc. V00'!W3:W60) -> 3 | ... AA4: =SUMIF('etc. V00'!$D$3:$D$60,"LPLN TOP 150 support",'etc. V00'!AO3:AO60) -> 0
A5: Total available HC | B5: =B1-SUM(B2:B4) -> 40.4 | C5: =C1-SUM(C2:C4) -> 40.4 | D5: =D1-SUM(D2:D4) -> 40.4 | E5: =E1-SUM(E2:E4) -> 39.4 | F5: =F1-SUM(F2:F4) -> 39.4 | G5: =G1-SUM(G2:G4) -> 39.4 | H5: =H1-SUM(H2:H4) -> 39.4 | I5: =I1-SUM(I2:I4) -> 40.1 | ... AA5: =AA1-SUM(AA2:AA4) -> 46.1
A7: 행 레이블 | B7: 합계 : 25-Nov | C7: 합계 : 25-Dec | D7: 합계 : 26-Jan | E7: 합계 : 26-Feb | F7: 합계 : 26-Mar | G7: 합계 : 26-Apr | H7: 합계 : 26-May | I7: 합계 : 26-Jun | J7: 합계 : 26-Jul | K7: 합계 : 26-Aug | L7: 합계 : 26-Sep | M7: 합계 : 26-Oct | N7: 합계 : 26-Nov | O7: 합계 : 26-Dec | P7: Sum of 27-Jan | Q7: Sum of 27-Feb | R7: Sum of 27-Mar | S7: Sum of 27-Apr | T7: Sum of 27-May | U7: Sum of 27-Jun | V7: Sum of 27-Jul | W7: Sum of 27-Aug | X7: Sum of 27-Sep | Y7: Sum of 27-Oct | Z7: Sum of 27-Nov | AA7: Sum of 27-Dec
A8: Control Eng. | B8: 13.5 | C8: 13.5 | D8: 14.5 | E8: 14.5 | F8: 14.5 | G8: 14.5 | H8: 14.5 | I8: 14.5 | J8: 14.5 | K8: 14.5 | L8: 14.5 | M8: 14.5 | N8: 14.5 | O8: 14.5 | P8: 14.5 | Q8: 14.5 | R8: 15.5 | S8: 15.5 | T8: 15.5 | U8: 15.5 | V8: 15.5 | W8: 15.5 | X8: 15.5 | Y8: 15.5 | Z8: 15.5 | AA8: 15.5
A9: Engineering | B9: 0.4 | C9: 0.4 | D9: 0.4 | E9: 0.4 | F9: 0.4 | G9: 0.4 | H9: 0.4 | I9: 0.4 | J9: 0.4 | K9: 0.4 | L9: 0.4 | M9: 0.4 | N9: 0.4 | O9: 0.4 | P9: 0.4 | Q9: 0.4 | R9: 0.4 | S9: 0.4 | T9: 0.4 | U9: 0.4 | V9: 0.4 | W9: 0.4 | X9: 0.4 | Y9: 0.4 | Z9: 0.4 | AA9: 0.4
A10: NPI IS | B10: 29 | C10: 29 | D10: 28 | E10: 27 | F10: 27 | G10: 27 | H10: 27 | I10: 27 | J10: 28 | K10: 28 | L10: 28 | M10: 28 | N10: 28 | O10: 29 | P10: 29 | Q10: 29 | R10: 29 | S10: 29 | T10: 29 | U10: 29 | V10: 29 | W10: 29 | X10: 29 | Y10: 29 | Z10: 29 | AA10: 29
A11: PMO | B11: 4 | C11: 4 | D11: 4 | E11: 4 | F11: 4 | G11: 4 | H11: 4 | I11: 4 | J11: 4 | K11: 4 | L11: 4 | M11: 4 | N11: 4 | O11: 4 | P11: 4 | Q11: 4 | R11: 4 | S11: 4 | T11: 4 | U11: 4 | V11: 4 | W11: 4 | X11: 4 | Y11: 4 | Z11: 4 | AA11: 4
A12: 총합계 | B12: 46.9 | C12: 46.9 | D12: 46.9 | E12: 45.9 | F12: 45.9 | G12: 45.9 | H12: 45.9 | I12: 45.9 | J12: 46.9 | K12: 46.9 | L12: 46.9 | M12: 46.9 | N12: 46.9 | O12: 47.9 | P12: 47.9 | Q12: 47.9 | R12: 48.9 | S12: 48.9 | T12: 48.9 | U12: 48.9 | V12: 48.9 | W12: 48.9 | X12: 48.9 | Y12: 48.9 | Z12: 48.9 | AA12: 48.9
A15: Engineer HC | B15: =GETPIVOTDATA("합계 : 25-Nov",$A$22) -> 41 | C15: =GETPIVOTDATA("합계 : 25-Nov",$A$22) -> 41 | D15: =GETPIVOTDATA("합계 : 25-Nov",$A$22) -> 41 | E15: =GETPIVOTDATA("합계 : 25-Nov",$A$22) -> 41 | F15: =GETPIVOTDATA("합계 : 25-Nov",$A$22) -> 41 | G15: =GETPIVOTDATA("합계 : 25-Nov",$A$22) -> 41 | H15: =GETPIVOTDATA("합계 : 25-Nov",$A$22) -> 41 | I15: =GETPIVOTDATA("합계 : 25-Nov",$A$22) -> 41 | ... AA15: =GETPIVOTDATA("합계 : 25-Nov",$A$22) -> 41
A16: TSG/파견 SW | B16: =SUM(B2:B3) -> 3.5 | C16: =SUM(C2:C3) -> 3.5 | D16: =SUM(D2:D3) -> 3.5 | E16: =SUM(E2:E3) -> 3.5 | F16: =SUM(F2:F3) -> 3.5 | G16: =SUM(G2:G3) -> 3.5 | H16: =SUM(H2:H3) -> 3.5 | I16: =SUM(I2:I3) -> 2.8 | ... AA16: =SUM(AA2:AA3) -> 2.8
A17: LPLN 파견 | B17: =B4 -> 3 | C17: =C4 -> 3 | D17: =D4 -> 3 | E17: =E4 -> 3 | F17: =F4 -> 3 | G17: =G4 -> 3 | H17: =H4 -> 3 | I17: =I4 -> 3 | ... AA17: =AA4 -> 0
A18: Available HC | B18: =B15-SUM(B16:B17) -> 34.5 | C18: =C15-SUM(C16:C17) -> 34.5 | D18: =D15-SUM(D16:D17) -> 34.5 | E18: =E15-SUM(E16:E17) -> 34.5 | F18: =F15-SUM(F16:F17) -> 34.5 | G18: =G15-SUM(G16:G17) -> 34.5 | H18: =H15-SUM(H16:H17) -> 34.5 | I18: =I15-SUM(I16:I17) -> 35.2 | ... AA18: =AA15-SUM(AA16:AA17) -> 38.2
A20: Resource role - engineering only
A22: 행 레이블 | B22: 합계 : 25-Nov | C22: 합계 : 25-Dec | D22: 합계 : 26-Jan | E22: 합계 : 26-Feb | F22: 합계 : 26-Mar | G22: 합계 : 26-Apr | H22: 합계 : 26-May | I22: 합계 : 26-Jun | J22: 합계 : 26-Jul | K22: 합계 : 26-Aug | L22: 합계 : 26-Sep | M22: 합계 : 26-Oct | N22: 합계 : 26-Nov | O22: 합계 : 26-Dec | P22: Sum of 27-Jan | Q22: Sum of 27-Feb | R22: Sum of 27-Mar | S22: Sum of 27-Apr | T22: Sum of 27-May | U22: Sum of 27-Jun | V22: Sum of 27-Jul | W22: Sum of 27-Aug | X22: Sum of 27-Sep | Y22: Sum of 27-Oct | Z22: Sum of 27-Nov | AA22: Sum of 27-Dec
A23: Electrical engineer | B23: 4 | C23: 4 | D23: 5 | E23: 5 | F23: 5 | G23: 5 | H23: 5 | I23: 5 | J23: 5 | K23: 5 | L23: 5 | M23: 5 | N23: 5 | O23: 5 | P23: 5 | Q23: 5 | R23: 5 | S23: 5 | T23: 5 | U23: 5 | V23: 5 | W23: 5 | X23: 5 | Y23: 5 | Z23: 5 | AA23: 5
A24: Mechanical engineer | B24: 7 | C24: 7 | D24: 7 | E24: 6 | F24: 6 | G24: 6 | H24: 6 | I24: 6 | J24: 7 | K24: 7 | L24: 7 | M24: 7 | N24: 7 | O24: 7 | P24: 7 | Q24: 7 | R24: 7 | S24: 7 | T24: 7 | U24: 7 | V24: 7 | W24: 7 | X24: 7 | Y24: 7 | Z24: 7 | AA24: 7
A25: PM | B25: 3 | C25: 3 | D25: 3 | E25: 3 | F25: 3 | G25: 3 | H25: 3 | I25: 3 | J25: 3 | K25: 3 | L25: 3 | M25: 3 | N25: 3 | O25: 3 | P25: 3 | Q25: 3 | R25: 3 | S25: 3 | T25: 3 | U25: 3 | V25: 3 | W25: 3 | X25: 3 | Y25: 3 | Z25: 3 | AA25: 3
A26: Service engineer | B26: 4 | C26: 4 | D26: 4 | E26: 4 | F26: 4 | G26: 4 | H26: 4 | I26: 4 | J26: 4 | K26: 4 | L26: 4 | M26: 4 | N26: 4 | O26: 4 | P26: 4 | Q26: 4 | R26: 4 | S26: 4 | T26: 4 | U26: 4 | V26: 4 | W26: 4 | X26: 4 | Y26: 4 | Z26: 4 | AA26: 4
A27: Software engineer | B27: 4 | C27: 4 | D27: 4 | E27: 4 | F27: 4 | G27: 4 | H27: 4 | I27: 4 | J27: 4 | K27: 4 | L27: 4 | M27: 4 | N27: 4 | O27: 4 | P27: 4 | Q27: 4 | R27: 5 | S27: 5 | T27: 5 | U27: 5 | V27: 5 | W27: 5 | X27: 5 | Y27: 5 | Z27: 5 | AA27: 5
A28: SW test engineer | B28: 3 | C28: 3 | D28: 3 | E28: 3 | F28: 3 | G28: 3 | H28: 3 | I28: 3 | J28: 3 | K28: 3 | L28: 3 | M28: 3 | N28: 3 | O28: 3 | P28: 3 | Q28: 3 | R28: 3 | S28: 3 | T28: 3 | U28: 3 | V28: 3 | W28: 3 | X28: 3 | Y28: 3 | Z28: 3 | AA28: 3
A29: System engineer | B29: 10 | C29: 10 | D29: 9 | E29: 9 | F29: 9 | G29: 9 | H29: 9 | I29: 9 | J29: 9 | K29: 9 | L29: 9 | M29: 9 | N29: 9 | O29: 10 | P29: 10 | Q29: 10 | R29: 10 | S29: 10 | T29: 10 | U29: 10 | V29: 10 | W29: 10 | X29: 10 | Y29: 10 | Z29: 10 | AA29: 10
A30: Tech Lead | B30: 6 | C30: 6 | D30: 6 | E30: 6 | F30: 6 | G30: 6 | H30: 6 | I30: 6 | J30: 6 | K30: 6 | L30: 6 | M30: 6 | N30: 6 | O30: 6 | P30: 6 | Q30: 6 | R30: 6 | S30: 6 | T30: 6 | U30: 6 | V30: 6 | W30: 6 | X30: 6 | Y30: 6 | Z30: 6 | AA30: 6
A31: Technician
A32: 총합계 | B32: 41 | C32: 41 | D32: 41 | E32: 40 | F32: 40 | G32: 40 | H32: 40 | I32: 40 | J32: 41 | K32: 41 | L32: 41 | M32: 41 | N32: 41 | O32: 42 | P32: 42 | Q32: 42 | R32: 43 | S32: 43 | T32: 43 | U32: 43 | V32: 43 | W32: 43 | X32: 43 | Y32: 43 | Z32: 43 | AA32: 43
A35: Resource role - All
A37: 행 레이블 | B37: 합계 : 25-Nov | C37: 합계 : 25-Dec | D37: 합계 : 26-Jan | E37: 합계 : 26-Feb | F37: 합계 : 26-Mar | G37: 합계 : 26-Apr | H37: 합계 : 26-May | I37: 합계 : 26-Jun | J37: 합계 : 26-Jul | K37: 합계 : 26-Aug | L37: 합계 : 26-Sep | M37: 합계 : 26-Oct | N37: 합계 : 26-Nov | O37: 합계 : 26-Dec | P37: Sum of 27-Jan | Q37: Sum of 27-Feb | R37: Sum of 27-Mar | S37: Sum of 27-Apr | T37: Sum of 27-May | U37: Sum of 27-Jun | V37: Sum of 27-Jul | W37: Sum of 27-Aug | X37: Sum of 27-Sep | Y37: Sum of 27-Oct | Z37: Sum of 27-Nov | AA37: Sum of 27-Dec
A38: Control Eng. | B38: 13.5 | C38: 13.5 | D38: 14.5 | E38: 14.5 | F38: 14.5 | G38: 14.5 | H38: 14.5 | I38: 14.5 | J38: 14.5 | K38: 14.5 | L38: 14.5 | M38: 14.5 | N38: 14.5 | O38: 14.5 | P38: 14.5 | Q38: 14.5 | R38: 15.5 | S38: 15.5 | T38: 15.5 | U38: 15.5 | V38: 15.5 | W38: 15.5 | X38: 15.5 | Y38: 15.5 | Z38: 15.5 | AA38: 15.5
A39: Engineering | B39: 0.4 | C39: 0.4 | D39: 0.4 | E39: 0.4 | F39: 0.4 | G39: 0.4 | H39: 0.4 | I39: 0.4 | J39: 0.4 | K39: 0.4 | L39: 0.4 | M39: 0.4 | N39: 0.4 | O39: 0.4 | P39: 0.4 | Q39: 0.4 | R39: 0.4 | S39: 0.4 | T39: 0.4 | U39: 0.4 | V39: 0.4 | W39: 0.4 | X39: 0.4 | Y39: 0.4 | Z39: 0.4 | AA39: 0.4
A40: NPI IS | B40: 29 | C40: 29 | D40: 28 | E40: 27 | F40: 27 | G40: 27 | H40: 27 | I40: 27 | J40: 28 | K40: 28 | L40: 28 | M40: 28 | N40: 28 | O40: 29 | P40: 29 | Q40: 29 | R40: 29 | S40: 29 | T40: 29 | U40: 29 | V40: 29 | W40: 29 | X40: 29 | Y40: 29 | Z40: 29 | AA40: 29
A41: PMO | B41: 4 | C41: 4 | D41: 4 | E41: 4 | F41: 4 | G41: 4 | H41: 4 | I41: 4 | J41: 4 | K41: 4 | L41: 4 | M41: 4 | N41: 4 | O41: 4 | P41: 4 | Q41: 4 | R41: 4 | S41: 4 | T41: 4 | U41: 4 | V41: 4 | W41: 4 | X41: 4 | Y41: 4 | Z41: 4 | AA41: 4
A42: 총합계 | B42: 46.9 | C42: 46.9 | D42: 46.9 | E42: 45.9 | F42: 45.9 | G42: 45.9 | H42: 45.9 | I42: 45.9 | J42: 46.9 | K42: 46.9 | L42: 46.9 | M42: 46.9 | N42: 46.9 | O42: 47.9 | P42: 47.9 | Q42: 47.9 | R42: 48.9 | S42: 48.9 | T42: 48.9 | U42: 48.9 | V42: 48.9 | W42: 48.9 | X42: 48.9 | Y42: 48.9 | Z42: 48.9 | AA42: 48.9

Sheet P2_부서
A1: 정원 - Plan | B1: =B12 -> 합계 : 25-Nov | C1: =C12 -> 합계 : 25-Dec | D1: =D12 -> 합계 : 26-Jan | E1: =E12 -> 합계 : 26-Feb | F1: =F12 -> 합계 : 26-Mar | G1: =G12 -> 합계 : 26-Apr | H1: =H12 -> 합계 : 26-May | I1: =I12 -> 합계 : 26-Jun | ... V1: =V12 -> Sum of 27-Dec
A2: =A13 -> Control Eng. | B2: =P1_정원!B8-B13 -> -3 | C2: =P1_정원!C8-C13 -> -2.5 | D2: =P1_정원!D8-D13 -> -4.1 | E2: =P1_정원!E8-E13 -> -3.9 | F2: =P1_정원!F8-F13 -> -3.8 | G2: =P1_정원!G8-G13 -> -4 | H2: =P1_정원!H8-H13 -> -3.5 | I2: =P1_정원!I8-I13 -> -2.8 | ... V2: =P1_정원!V8-V13 -> 8.7
A3: =A14 -> Engineering | B3: =P1_정원!B9-B14 -> 0 | C3: =P1_정원!C9-C14 -> 0 | D3: =P1_정원!D9-D14 -> -0.1 | E3: =P1_정원!E9-E14 -> -0.1 | F3: =P1_정원!F9-F14 -> -0.1 | G3: =P1_정원!G9-G14 -> 0 | H3: =P1_정원!H9-H14 -> 0 | I3: =P1_정원!I9-I14 -> 0 | ... V3: =P1_정원!V9-V14 -> 0.3
A4: =A15 -> NPI IS | B4: =P1_정원!B10-B15 -> 1.6 | C4: =P1_정원!C10-C15 -> -0.8 | D4: =P1_정원!D10-D15 -> 1 | E4: =P1_정원!E10-E15 -> 0.6 | F4: =P1_정원!F10-F15 -> 0.7 | G4: =P1_정원!G10-G15 -> 1.4 | H4: =P1_정원!H10-H15 -> 1.4 | I4: =P1_정원!I10-I15 -> 1.5 | ... V4: =P1_정원!V10-V15 -> 22.7
A5: =A16 -> PMO | B5: =P1_정원!B11-B16 -> -0.4 | C5: =P1_정원!C11-C16 -> -0.5 | D5: =P1_정원!D11-D16 -> -0.8 | E5: =P1_정원!E11-E16 -> -0.7 | F5: =P1_정원!F11-F16 -> -0.6 | G5: =P1_정원!G11-G16 -> -0.2 | H5: =P1_정원!H11-H16 -> -0.2 | I5: =P1_정원!I11-I16 -> -0.2 | ... V5: =P1_정원!V11-V16 -> 3.4
A6: =A17 -> 총합계 | B6: =P1_정원!B12-B17 -> -1.8 | C6: =P1_정원!C12-C17 -> -3.8 | D6: =P1_정원!D12-D17 -> -4 | E6: =P1_정원!E12-E17 -> -4.1 | F6: =P1_정원!F12-F17 -> -3.8 | G6: =P1_정원!G12-G17 -> -2.8 | H6: =P1_정원!H12-H17 -> -2.3 | I6: =P1_정원!I12-I17 -> -1.5 | ... V6: =P1_정원!V12-V17 -> 35.1
B7: =P1_정원!B13-B18 -> 0 | C7: =P1_정원!C13-C18 -> 0 | D7: =P1_정원!D13-D18 -> 0 | E7: =P1_정원!E13-E18 -> 0 | F7: =P1_정원!F13-F18 -> 0 | G7: =P1_정원!G13-G18 -> 0 | H7: =P1_정원!H13-H18 -> 0 | I7: =P1_정원!I13-I18 -> 0 | ... T7: =P1_정원!T13-T18 -> 0
A9: Project | B9: (모두)
A10: Status | B10: (다중 항목)
A12: 행 레이블 | B12: 합계 : 25-Nov | C12: 합계 : 25-Dec | D12: 합계 : 26-Jan | E12: 합계 : 26-Feb | F12: 합계 : 26-Mar | G12: 합계 : 26-Apr | H12: 합계 : 26-May | I12: 합계 : 26-Jun | J12: 합계 : 26-Jul | K12: 합계 : 26-Aug | L12: 합계 : 26-Sep | M12: 합계 : 26-Oct | N12: 합계 : 26-Nov | O12: 합계 : 26-Dec | P12: Sum of 27-Jan | Q12: Sum of 27-Feb | R12: Sum of 27-May | S12: Sum of 27-Jun | T12: Sum of 27-Oct | U12: Sum of 27-Nov | V12: Sum of 27-Dec
A13: Control Eng. | B13: 16.5 | C13: 16 | D13: 18.6 | E13: 18.4 | F13: 18.3 | G13: 18.5 | H13: 18 | I13: 17.3 | J13: 18.6 | K13: 17.3 | L13: 17.1 | M13: 17.1 | N13: 17.1 | O13: 17.1 | P13: 17.1 | Q13: 18.1 | R13: 18 | S13: 18 | T13: 10.1 | U13: 6.8 | V13: 6.8
A14: Engineering | B14: 0.4 | C14: 0.4 | D14: 0.5 | E14: 0.5 | F14: 0.5 | G14: 0.4 | H14: 0.4 | I14: 0.4 | J14: 0.5 | K14: 0.4 | L14: 0.3 | M14: 0.3 | N14: 0.3 | O14: 0.3 | P14: 0.3 | Q14: 0.3 | R14: 0.3 | S14: 0.3 | T14: 0.2 | U14: 0.1 | V14: 0.1
A15: NPI IS | B15: 27.4 | C15: 29.8 | D15: 27 | E15: 26.4 | F15: 26.3 | G15: 25.6 | H15: 25.6 | I15: 25.5 | J15: 30.2 | K15: 27 | L15: 23.7 | M15: 27.7 | N15: 27.7 | O15: 27.7 | P15: 24.7 | Q15: 24.7 | R15: 24.6 | S15: 24.6 | T15: 13 | U15: 6.3 | V15: 6.3
A16: PMO | B16: 4.4 | C16: 4.5 | D16: 4.8 | E16: 4.7 | F16: 4.6 | G16: 4.2 | H16: 4.2 | I16: 4.2 | J16: 4.9 | K16: 4.3 | L16: 3.6 | M16: 3.6 | N16: 3.6 | O16: 3.6 | P16: 3.5 | Q16: 3.5 | R16: 2.9 | S16: 2.9 | T16: 1.2 | U16: 0.6 | V16: 0.6
A17: 총합계 | B17: 48.7 | C17: 50.7 | D17: 50.9 | E17: 50 | F17: 49.7 | G17: 48.7 | H17: 48.2 | I17: 47.4 | J17: 54.2 | K17: 49 | L17: 44.7 | M17: 48.7 | N17: 48.7 | O17: 48.7 | P17: 45.6 | Q17: 46.6 | R17: 45.8 | S17: 45.8 | T17: 24.5 | U17: 13.8 | V17: 13.8

Sheet P3_PRJ total gap
B1: =B9 -> 합계 : 25-Nov | C1: =C9 -> 합계 : 25-Dec | D1: =D9 -> 합계 : 26-Jan | E1: =E9 -> 합계 : 26-Feb | F1: =F9 -> 합계 : 26-Mar | G1: =G9 -> 합계 : 26-Apr | H1: =H9 -> 합계 : 26-May | I1: =I9 -> 합계 : 26-Jun | ... V1: =V9 -> Sum of 27-Dec
A2: Total HC VS Plan | B2: =B3-B25 -> 46.9 | C2: =C3-C25 -> 46.9 | D2: =D3-D25 -> 46.9 | E2: =E3-E25 -> 45.9 | F2: =F3-F25 -> 45.9 | G2: =G3-G25 -> 45.9 | H2: =H3-H25 -> 45.9 | I2: =I3-I25 -> 45.9 | ... V2: =V3-V25 -> 48.9
A3: Total HC | B3: =P1_정원!B12 -> 46.9 | C3: =P1_정원!C12 -> 46.9 | D3: =P1_정원!D12 -> 46.9 | E3: =P1_정원!E12 -> 45.9 | F3: =P1_정원!F12 -> 45.9 | G3: =P1_정원!G12 -> 45.9 | H3: =P1_정원!H12 -> 45.9 | I3: =P1_정원!I12 -> 45.9 | ... R3: =P1_정원!R12 -> 48.9 | S3: =P1_정원!U12 -> 48.9 | T3: =P1_정원!V12 -> 48.9 | U3: =P1_정원!W12 -> 48.9 | V3: =P1_정원!X12 -> 48.9
A6: Status | B6: (다중 항목)
A7: Resource Role | B7: (모두)
A9: 행 레이블 | B9: 합계 : 25-Nov | C9: 합계 : 25-Dec | D9: 합계 : 26-Jan | E9: 합계 : 26-Feb | F9: 합계 : 26-Mar | G9: 합계 : 26-Apr | H9: 합계 : 26-May | I9: 합계 : 26-Jun | J9: 합계 : 26-Jul | K9: 합계 : 26-Aug | L9: 합계 : 26-Sep | M9: 합계 : 26-Oct | N9: 합계 : 26-Nov | O9: 합계 : 26-Dec | P9: Sum of 27-Jan | Q9: Sum of 27-Feb | R9: Sum of 27-May | S9: Sum of 27-Jun | T9: Sum of 27-Oct | U9: Sum of 27-Nov | V9: Sum of 27-Dec
A10: CatOX Alpha design | B10: 0.5 | C10: 0 | D10: 0 | E10: 0 | F10: 0 | G10: 0 | H10: 0 | I10: 0 | J10: 0 | K10: 0 | L10: 0 | M10: 0 | N10: 0 | O10: 0 | P10: 0 | Q10: 0 | R10: 0 | S10: 0 | T10: 0 | U10: 0 | V10: 0
A11: Ganymede support - PCCA | B11: 0 | C11: 0 | D11: 0 | E11: 0 | F11: 0 | G11: 0 | H11: 0 | I11: 0 | J11: 0 | K11: 0 | L11: 0 | M11: 0 | N11: 0 | O11: 0 | P11: 0 | Q11: 0 | R11: 0 | S11: 0 | T11: 0 | U11: 0 | V11: 0
A12: Havasu | B12: 5.3 | C12: 4.8 | D12: 1.5 | E12: 0.6 | F12: 0.6 | G12: 0 | H12: 0 | I12: 0 | J12: 0 | K12: 0 | L12: 0 | M12: 0 | N12: 0 | O12: 0 | P12: 0 | Q12: 0 | R12: 0 | S12: 0 | T12: 0 | U12: 0 | V12: 0
A13: HRS Integrates | B13: 5.1 | C13: 4.3 | D13: 0.4 | E13: 0.4 | F13: 0.4 | G13: 0 | H13: 0 | I13: 0 | J13: 0 | K13: 0 | L13: 0 | M13: 0 | N13: 0 | O13: 0 | P13: 0 | Q13: 0 | R13: 0 | S13: 0 | T13: 0 | U13: 0 | V13: 0
A14: Micron A&D | B14: 4.4 | C14: 8.4 | D14: 9.5 | E14: 10 | F14: 10 | G14: 9 | H14: 9 | I14: 9 | J14: 9 | K14: 0 | L14: 0 | M14: 0 | N14: 0 | O14: 0 | P14: 0 | Q14: 0 | R14: 0 | S14: 0 | T14: 0 | U14: 0 | V14: 0
A15: R&D General - Legacy/TSG | B15: 2 | C15: 2 | D15: 2 | E15: 2 | F15: 2 | G15: 2 | H15: 2 | I15: 2 | J15: 2 | K15: 2 | L15: 2 | M15: 2 | N15: 2 | O15: 2 | P15: 2 | Q15: 2 | R15: 2 | S15: 2 | T15: 2 | U15: 2 | V15: 2
A16: Tumalo Ph1 | B16: 12.1 | C16: 12.1 | D16: 8.4 | E16: 8.4 | F16: 7.9 | G16: 7.3 | H16: 6.8 | I16: 6.7 | J16: 6.7 | K16: 6.7 | L16: 0 | M16: 0 | N16: 0 | O16: 0 | P16: 0 | Q16: 0 | R16: 0 | S16: 0 | T16: 0 | U16: 0 | V16: 0
A17: Tumalo Ph2 | B17: 9.6 | C17: 9.6 | D17: 12.4 | E17: 12.4 | F17: 12.6 | G17: 13.2 | H17: 13.2 | I17: 13.2 | J17: 14.2 | K17: 16 | L17: 16 | M17: 16 | N17: 16 | O17: 16 | P17: 16.4 | Q17: 16.4 | R17: 15.6 | S17: 15.6 | T17: 0 | U17: 0 | V17: 0
A18: Unify support | B18: 1.5 | C18: 1.5 | D18: 1.5 | E18: 1.5 | F18: 1.5 | G18: 1.5 | H18: 1.5 | I18: 0.8 | J18: 0.8 | K18: 0.8 | L18: 0.8 | M18: 0.8 | N18: 0.8 | O18: 0.8 | P18: 0.8 | Q18: 0.8 | R18: 0.8 | S18: 0.8 | T18: 0.8 | U18: 0.8 | V18: 0.8
A19: Gen3 EUV Zenith Plus 7SRC TSMC | B19: 5.2 | C19: 2.8 | D19: 0 | E19: 0 | F19: 0 | G19: 0 | H19: 0 | I19: 0 | J19: 0 | K19: 0 | L19: 0 | M19: 0 | N19: 0 | O19: 0 | P19: 0 | Q19: 0 | R19: 0 | S19: 0 | T19: 0 | U19: 0 | V19: 0
A20: LPLN TOP 150 support | B20: 3 | C20: 3 | D20: 3 | E20: 3 | F20: 3 | G20: 3 | H20: 3 | I20: 3 | J20: 3 | K20: 3 | L20: 3 | M20: 3 | N20: 3 | O20: 3 | P20: 0 | Q20: 0 | R20: 0 | S20: 0 | T20: 0 | U20: 0 | V20: 0
A21: Kanara | B21: 0 | C21: 0 | D21: 0 | E21: 0 | F21: 0 | G21: 0 | H21: 0 | I21: 0 | J21: 5.8 | K21: 6.8 | L21: 9.2 | M21: 13.2 | N21: 13.2 | O21: 13.2 | P21: 13.2 | Q21: 14.2 | R21: 14.2 | S21: 14.2 | T21: 11 | U21: 11 | V21: 11
... A23: 총합계 | B23: 48.7 | C23: 50.7 | D23: 50.9 | E23: 50 | F23: 49.7 | G23: 48.7 | H23: 48.2 | I23: 47.4 | J23: 54.2 | K23: 49 | L23: 44.7 | M23: 48.7 | N23: 48.7 | O23: 48.7 | P23: 45.6 | Q23: 46.6 | R23: 45.8 | S23: 45.8 | T23: 24.5 | U23: 13.8 | V23: 13.8

Sheet P3_PRJ engineer gap
A1: Total HC VS Plan | B1: =B20 -> 합계 : 25-Nov | C1: =C20 -> 합계 : 25-Dec | D1: =D20 -> 합계 : 26-Jan | E1: =E20 -> 합계 : 26-Feb | F1: =F20 -> 합계 : 26-Mar | G1: =G20 -> 합계 : 26-Apr | H1: =H20 -> 합계 : 26-May | I1: =I20 -> 합계 : 26-Jun | ... AA1: =AA20 -> Sum of 27-Dec
A2: =A21 -> Electrical engineer | B2: =P1_정원!B23-B21 -> 0 | C2: =P1_정원!C23-C21 -> -0.5 | D2: =P1_정원!D23-D21 -> -0.3 | E2: =P1_정원!E23-E21 -> -0.1 | F2: =P1_정원!F23-F21 -> -0.1 | G2: =P1_정원!G23-G21 -> 0 | H2: =P1_정원!H23-H21 -> 0 | I2: =P1_정원!I23-I21 -> 0 | ... AA2: =P1_정원!AA23-AA21 -> 3.5
A3: =A22 -> Mechanical engineer | B3: =P1_정원!B24-B22 -> 1 | C3: =P1_정원!C24-C22 -> -0.5 | D3: =P1_정원!D24-D22 -> 1 | E3: =P1_정원!E24-E22 -> 0 | F3: =P1_정원!F24-F22 -> 0 | G3: =P1_정원!G24-G22 -> 0 | H3: =P1_정원!H24-H22 -> 0 | I3: =P1_정원!I24-I22 -> 0 | ... AA3: =P1_정원!AA24-AA22 -> 5
A4: =A23 -> PM | B4: =P1_정원!B25-B23 -> -0.2 | C4: =P1_정원!C25-C23 -> -0.1 | D4: =P1_정원!D25-D23 -> -0.7 | E4: =P1_정원!E25-E23 -> -0.6 | F4: =P1_정원!F25-F23 -> -0.6 | G4: =P1_정원!G25-G23 -> -0.4 | H4: =P1_정원!H25-H23 -> -0.4 | I4: =P1_정원!I25-I23 -> -0.4 | ... AA4: =P1_정원!AA25-AA23 -> 2.5
A5: =A24 -> Service engineer | B5: =P1_정원!B26-B24 -> 0.3 | C5: =P1_정원!C26-C24 -> 0 | D5: =P1_정원!D26-D24 -> -0.5 | E5: =P1_정원!E26-E24 -> -0.2 | F5: =P1_정원!F26-F24 -> -0.2 | G5: =P1_정원!G26-G24 -> 0 | H5: =P1_정원!H26-H24 -> 0 | I5: =P1_정원!I26-I24 -> 0 | ... AA5: =P1_정원!AA26-AA24 -> 4
A6: =A25 -> Software engineer | B6: =P1_정원!B27-B25 -> -2.2 | C6: =P1_정원!C27-C25 -> -1.7 | D6: =P1_정원!D27-D25 -> -2.7 | E6: =P1_정원!E27-E25 -> -2.7 | F6: =P1_정원!F27-F25 -> -2.7 | G6: =P1_정원!G27-G25 -> -2.2 | H6: =P1_정원!H27-H25 -> -2.2 | I6: =P1_정원!I27-I25 -> -1.7 | ... AA6: =P1_정원!AA27-AA25 -> 2.5
A7: =A26 -> SW test engineer | B7: =P1_정원!B28-B26 -> -1 | C7: =P1_정원!C28-C26 -> -0.5 | D7: =P1_정원!D28-D26 -> -1 | E7: =P1_정원!E28-E26 -> -1 | F7: =P1_정원!F28-F26 -> -1 | G7: =P1_정원!G28-G26 -> -2 | H7: =P1_정원!H28-H26 -> -1.5 | I7: =P1_정원!I28-I26 -> -1.5 | ... AA7: =P1_정원!AA28-AA26 -> 1
A8: =A27 -> System engineer | B8: =P1_정원!B29-B27 -> 0 | C8: =P1_정원!C29-C27 -> 0 | D8: =P1_정원!D29-D27 -> 0 | E8: =P1_정원!E29-E27 -> 0 | F8: =P1_정원!F29-F27 -> 0 | G8: =P1_정원!G29-G27 -> 0 | H8: =P1_정원!H29-H27 -> 0 | I8: =P1_정원!I29-I27 -> 0 | ... AA8: =P1_정원!AA29-AA27 -> 7
A9: =A28 -> Tech Lead | B9: =P1_정원!B30-B28 -> 0.3 | C9: =P1_정원!C30-C28 -> 0 | D9: =P1_정원!D30-D28 -> 0.5 | E9: =P1_정원!E30-E28 -> 0.8 | F9: =P1_정원!F30-F28 -> 0.8 | G9: =P1_정원!G30-G28 -> 1 | H9: =P1_정원!H30-H28 -> 1 | I9: =P1_정원!I30-I28 -> 1 | ... AA9: =P1_정원!AA30-AA28 -> 6
A10: =A29 -> Technician | B10: =P1_정원!B31-B29 -> 0 | C10: =P1_정원!C31-C29 -> 0 | D10: =P1_정원!D31-D29 -> 0 | E10: =P1_정원!E31-E29 -> 0 | F10: =P1_정원!F31-F29 -> 0 | G10: =P1_정원!G31-G29 -> 0 | H10: =P1_정원!H31-H29 -> 0 | I10: =P1_정원!I31-I29 -> 0 | ... AA10: =P1_정원!AA31-AA29 -> 0
A11: =A30 -> 총합계 | B11: =P1_정원!B32-B30 -> -1.8 | C11: =P1_정원!C32-C30 -> -3.3 | D11: =P1_정원!D32-D30 -> -3.7 | E11: =P1_정원!E32-E30 -> -3.8 | F11: =P1_정원!F32-F30 -> -3.8 | G11: =P1_정원!G32-G30 -> -3.6 | H11: =P1_정원!H32-H30 -> -3.1 | I11: =P1_정원!I32-I30 -> -2.6 | ... AA11: =P1_정원!AA32-AA30 -> 31.5
A14: Functional Engineer Requirement
A15: Resource Department | B15: (모두)
A16: Status | B16: (다중 항목)
A17: PJT Lifecycle | B17: (모두)
A18: Project | B18: (다중 항목)
A20: 행 레이블 | B20: 합계 : 25-Nov | C20: 합계 : 25-Dec | D20: 합계 : 26-Jan | E20: 합계 : 26-Feb | F20: 합계 : 26-Mar | G20: 합계 : 26-Apr | H20: 합계 : 26-May | I20: 합계 : 26-Jun | J20: 합계 : 26-Jul | K20: 합계 : 26-Aug | L20: Sum of 26-Sep | M20: Sum of 26-Oct | N20: 합계 : 26-Nov | O20: 합계 : 26-Dec | P20: Sum of 27-Jan | Q20: Sum of 27-Feb | R20: 합계 : 27-Mar | S20: 합계 : 27-Apr | T20: Sum of 27-May | U20: Sum of 27-Jun | V20: 합계 : 27-Jul | W20: 합계 : 27-Aug | X20: 합계 : 27-Sep | Y20: Sum of 27-Oct | Z20: Sum of 27-Nov | AA20: Sum of 27-Dec
A21: Electrical engineer | B21: 4 | C21: 4.5 | D21: 5.3 | E21: 5.1 | F21: 5.1 | G21: 5 | H21: 5 | I21: 5 | J21: 5 | K21: 4 | L21: 5 | M21: 5 | N21: 5 | O21: 5 | P21: 5 | Q21: 5 | R21: 5 | S21: 5 | T21: 5 | U21: 5 | V21: 4.5 | W21: 4.5 | X21: 4 | Y21: 2 | Z21: 1.5 | AA21: 1.5
A22: Mechanical engineer | B22: 6 | C22: 7.5 | D22: 6 | E22: 6 | F22: 6 | G22: 6 | H22: 6 | I22: 6 | J22: 8 | K22: 7.5 | L22: 7 | M22: 9 | N22: 9 | O22: 9 | P22: 9 | Q22: 9 | R22: 9 | S22: 9 | T22: 9 | U22: 9 | V22: 8.5 | W22: 8.5 | X22: 7.5 | Y22: 4.5 | Z22: 2 | AA22: 2
A23: PM | B23: 3.2 | C23: 3.1 | D23: 3.7 | E23: 3.6 | F23: 3.6 | G23: 3.4 | H23: 3.4 | I23: 3.4 | J23: 3.9 | K23: 3.5 | L23: 3 | M23: 3 | N23: 3 | O23: 3 | P23: 3 | Q23: 3 | R23: 3 | S23: 3 | T23: 2.5 | U23: 2.5 | V23: 2 | W23: 2 | X23: 2 | Y23: 1 | Z23: 0.5 | AA23: 0.5
A24: Service engineer | B24: 3.7 | C24: 4 | D24: 4.5 | E24: 4.2 | F24: 4.2 | G24: 4 | H24: 4 | I24: 4 | J24: 4 | K24: 4.6 | L24: 4 | M24: 5 | N24: 5 | O24: 5 | P24: 4 | Q24: 4 | R24: 4 | S24: 4 | T24: 4 | U24: 4 | V24: 4 | W24: 4 | X24: 3 | Y24: 2 | Z24: 0 | AA24: 0
A25: Software engineer | B25: 6.2 | C25: 5.7 | D25: 6.7 | E25: 6.7 | F25: 6.7 | G25: 6.2 | H25: 6.2 | I25: 5.7 | J25: 6.7 | K25: 7.5 | L25: 7.5 | M25: 7.5 | N25: 7.5 | O25: 7.5 | P25: 7.5 | Q25: 7.5 | R25: 7.5 | S25: 7.5 | T25: 7.5 | U25: 7.5 | V25: 7.5 | W25: 7.5 | X25: 7.5 | Y25: 4.5 | Z25: 2.5 | AA25: 2.5
A26: SW test engineer | B26: 4 | C26: 3.5 | D26: 4 | E26: 4 | F26: 4 | G26: 5 | H26: 4.5 | I26: 4.5 | J26: 4.5 | K26: 4 | L26: 3 | M26: 3 | N26: 3 | O26: 3 | P26: 3 | Q26: 4 | R26: 4 | S26: 4 | T26: 4 | U26: 4 | V26: 4 | W26: 4 | X26: 4 | Y26: 2.5 | Z26: 2 | AA26: 2
A27: System engineer | B27: 10 | C27: 10 | D27: 9 | E27: 9 | F27: 9 | G27: 9 | H27: 9 | I27: 9 | J27: 11 | K27: 8.7 | L27: 7 | M27: 8 | N27: 8 | O27: 8 | P27: 7 | Q27: 7 | R27: 7 | S27: 7 | T27: 7 | U27: 7 | V27: 6.5 | W27: 6.5 | X27: 6.5 | Y27: 4.5 | Z27: 3 | AA27: 3
A28: Tech Lead | B28: 5.7 | C28: 6 | D28: 5.5 | E28: 5.2 | F28: 5.2 | G28: 5 | H28: 5 | I28: 5 | J28: 5 | K28: 4 | L28: 3.5 | M28: 3.5 | N28: 3.5 | O28: 3.5 | P28: 2.5 | Q28: 2.5 | R28: 2.5 | S28: 2.5 | T28: 2.5 | U28: 2.5 | V28: 2 | W28: 2 | X28: 2 | Y28: 0.5 | Z28: 0 | AA28: 0
A29: Technician | B29: 0 | C29: 0 | D29: 0 | E29: 0 | F29: 0 | G29: 0 | H29: 0 | I29: 0 | J29: 0 | K29: 0 | L29: 0 | M29: 0 | N29: 0 | O29: 0 | P29: 0 | Q29: 0 | R29: 0 | S29: 0 | T29: 0 | U29: 0 | V29: 0 | W29: 0 | X29: 0 | Y29: 0 | Z29: 0 | AA29: 0
A30: 총합계 | B30: 42.8 | C30: 44.3 | D30: 44.7 | E30: 43.8 | F30: 43.8 | G30: 43.6 | H30: 43.1 | I30: 42.6 | J30: 48.1 | K30: 43.8 | L30: 40 | M30: 44 | N30: 44 | O30: 44 | P30: 41 | Q30: 42 | R30: 42 | S30: 42 | T30: 41.5 | U30: 41.5 | V30: 39 | W30: 39 | X30: 36.5 | Y30: 21.5 | Z30: 11.5 | AA30: 11.5
A35: Project Requirement
A37: Resource Department | B37: (모두)
A38: Status | B38: (다중 항목)
A39: PJT Lifecycle | B39: (모두)
A41: 행 레이블 | B41: 합계 : 25-Nov | C41: 합계 : 25-Dec | D41: 합계 : 26-Jan | E41: 합계 : 26-Feb | F41: 합계 : 26-Mar | G41: 합계 : 26-Apr | H41: 합계 : 26-May | I41: 합계 : 26-Jun | J41: 합계 : 26-Jul | K41: 합계 : 26-Aug | L41: 합계 : 26-Nov | M41: 합계 : 26-Dec | N41: Sum of 27-Jan | O41: Sum of 27-Feb | P41: Sum of 27-May | Q41: Sum of 27-Jun | R41: Sum of 27-Oct | S41: Sum of 27-Nov | T41: Sum of 27-Dec
A42: CatOX Alpha design | B42: 0.5 | C42: 0 | D42: 0 | E42: 0 | F42: 0 | G42: 0 | H42: 0 | I42: 0 | J42: 0 | K42: 0 | L42: 0 | M42: 0 | N42: 0 | O42: 0 | P42: 0 | Q42: 0 | R42: 0 | S42: 0 | T42: 0
A43: Ganymede support - PCCA | B43: 0 | C43: 0 | D43: 0 | E43: 0 | F43: 0 | G43: 0 | H43: 0 | I43: 0 | J43: 0 | K43: 0 | L43: 0 | M43: 0 | N43: 0 | O43: 0 | P43: 0 | Q43: 0 | R43: 0 | S43: 0 | T43: 0
A44: Havasu | B44: 4.6 | C44: 4.1 | D44: 1.5 | E44: 0.6 | F44: 0.6 | G44: 0 | H44: 0 | I44: 0 | J44: 0 | K44: 0 | L44: 0 | M44: 0 | N44: 0 | O44: 0 | P44: 0 | Q44: 0 | R44: 0 | S44: 0 | T44: 0
A45: HRS Integrates | B45: 4.9 | C45: 3.7 | D45: 0.2 | E45: 0.2 | F45: 0.2 | G45: 0 | H45: 0 | I45: 0 | J45: 0 | K45: 0 | L45: 0 | M45: 0 | N45: 0 | O45: 0 | P45: 0 | Q45: 0 | R45: 0 | S45: 0 | T45: 0
A46: Micron A&D | B46: 3.4 | C46: 7.1 | D46: 8.1 | E46: 8.6 | F46: 8.6 | G46: 7.6 | H46: 7.6 | I46: 7.6 | J46: 7.6 | K46: 0 | L46: 0 | M46: 0 | N46: 0 | O46: 0 | P46: 0 | Q46: 0 | R46: 0 | S46: 0 | T46: 0
A47: R&D General - Legacy/TSG | B47: 2 | C47: 2 | D47: 2 | E47: 2 | F47: 2 | G47: 2 | H47: 2 | I47: 2 | J47: 2 | K47: 2 | L47: 2 | M47: 2 | N47: 2 | O47: 2 | P47: 2 | Q47: 2 | R47: 2 | S47: 2 | T47: 2
A48: Tumalo Ph1 | B48: 10.4 | C48: 10.5 | D48: 6.9 | E48: 6.9 | F48: 6.8 | G48: 6.3 | H48: 5.8 | I48: 5.8 | J48: 5.8 | K48: 5.8 | L48: 0 | M48: 0 | N48: 0 | O48: 0 | P48: 0 | Q48: 0 | R48: 0 | S48: 0 | T48: 0
A49: Tumalo Ph2 | B49: 8.5 | C49: 8.4 | D49: 11 | E49: 11 | F49: 11.1 | G49: 11.7 | H49: 11.7 | I49: 11.7 | J49: 12.7 | K49: 14.5 | L49: 14.5 | M49: 14.5 | N49: 15 | O49: 15 | P49: 14.5 | Q49: 14.5 | R49: 0 | S49: 0 | T49: 0
...

Sheet P4_Name
A2: Status | B2: Active
A3: Resource Department | B3: (다중 항목)
A5: 행 레이블 | B5: 합계 : 25-Jun | C5: 합계 : 25-Jul | D5: 합계 : 25-Aug | E5: 합계 : 25-Sep | F5: 합계 : 25-Oct | G5: 합계 : 25-Nov | H5: 합계 : 25-Dec | I5: 합계 : 26-Jan | J5: 합계 : 26-Feb | K5: 합계 : 26-Mar | L5: 합계 : 26-Apr | M5: 합계 : 26-May | N5: 합계 : 26-Jun | O5: 합계 : 26-Jul | P5: 합계 : 26-Aug | Q5: 합계 : 26-Sep | R5: 합계 : 26-Oct | S5: 합계 : 26-Nov | T5: 합계 : 26-Dec
